Workbook

Sheet ACTUAL PLAYOFFS
A1: =IFERROR(__xludf.DUMMYFUNCTION("IMPORTRANGE(""https://docs.google.com/spreadsheets/d/1F6iikF3GEJXf_9wiDRCWbYz6xR6PARMk7zGTrILsbIE/edit?gid=1462027705#gid=1462027705"",""Playoffs!a1:x56"")"),"#REF!") -> #REF!

Sheet Week 1
A1: Date & Time (EST) | B1: Week 1 Matchup | C1: Actual | G1: Jon | L1: Alisha | Q1: Carson | V1: Nok | AA1: Mango | AF1: Caleb | AK1: Ross | AP1: Dishman | AU1: Ethan | AZ1: Brett | BE1: Wells | BJ1: Rob
A2: Wed 9/9 @ 7:20pm | B2: NE @ SEA | C2: =IFERROR(__xludf.DUMMYFUNCTION("IMPORTRANGE(""https://docs.google.com/spreadsheets/d/1v9a6MxzpyXdVbef97sptWrOJUpuAu6ldKC6wbegqpyg/edit?gid=0#gid=0"",""Week 1!C3:F18"")"),"SEA") -> SEA | D2: =IFERROR(__xludf.DUMMYFUNCTION("""COMPUTED_VALUE"""),"") | E2: =IFERROR(__xludf.DUMMYFUNCTION("""COMPUTED_VALUE"""),10.0) -> 10 | F2: =IFERROR(__xludf.DUMMYFUNCTION("""COMPUTED_VALUE"""),13.0) -> 13 | G2: SEA | H2: =IF(G2="KC",IMAGE("https://logodownload.org/wp-content/uploads/2020/09/kansas-city-chiefs-logo.png"),IF(G2="LV",IMAGE("https://logodownload.org/wp-content/uploads/2020/09/las-vegas-raiders-logo-1-564x599.png"),IF(G2="DEN",IMAGE("https://logodownload.org/wp-content/uploads/2020/07/denver-broncos-logo-0.png"),IF(G2="LAC",IMAGE("https://logosmarcas.net/wp-content/uploads/2020/07/Los-Angeles-Chargers-logo.png"),IF(G2="BUF",IMAGE("https://logos-download.com/wp-content/uploads/2018/03/Buffalo_Bills_logo_blue.png"),IF(G2="MIA",IMAGE("https://logos-world.net/wp-content/uploads/2020/05/Miami-Dolphins-Logo.png"),IF(G2="NYJ",IMAGE("https://logos-world.net/wp-content/uploads/2020/07/New-York-Jets-Logo.png"),IF(G2="NE",IMAGE("https://purepng.com/public/uploads/large/new-england-patriots-logo-symbol-ucp.png"),IF(G2="BAL",IMAGE("https://1000logos.net/wp-content/uploads/2016/10/Baltimore-Ravens-Logo.png"),IF(G2="CLE",IMAGE("https://logos-world.net/wp-content/uploads/2020/05/Cleveland-Browns-Logo-2006-2014.png"),IF(G2="PIT",IMAGE("https://1000logos.net/wp-content/uploads/2017/06/Pittsburgh-Steelers-Logo.png"),IF(G2="CIN",IMAGE("https://logos-world.net/wp-content/uploads/2020/05/Cincinnati-Bengals-Logo.png"),IF(G2="HOU",IMAGE("https://cdn.wallpapersafari.com/15/25/Jnl2Yc.png"),IF(G2="JAX",IMAGE("https://1000logos.net/wp-content/uploads/2018/07/Jacksonville-Jaguars-Logo-1536x960.png"),IF(G2="IND",IMAGE("https://1000logos.net/wp-content/uploads/2016/12/Indianapolis-Colts-Logo-2048x1280.png"),IF(G2="TEN",IMAGE("https://img-s-msn-com.akamaized.net/tenant/amp/entityid/AA1YwbtK.img?w=720&h=720&m=6"),IF(G2="SF",IMAGE("https://logodownload.org/wp-content/uploads/2020/09/san-francisco-49ers-logo-2048x1220.png"),IF(G2="LAR",IMAGE("https://1000logos.net/wp-content/uploads/2018/07/Rams-Logo.png"),IF(G2="SEA",IMAGE("https://cdn.freebiesupply.com/images/large/2x/seattle-seahawks-logo-transparent.png"),IF(G2="AZ",IMAGE("https://logos-world.net/wp-content/uploads/2020/05/Arizona-Cardinals-Logo.png"),IF(G2="DAL",IMAGE("https://www.freepnglogos.com/uploads/dallas-cowboys-logo-22.png"),IF(G2="PHI",IMAGE("https://1000logos.net/wp-content/uploads/2017/05/Philadelphia-Eagles-Logo.png"),IF(G2="NYG",IMAGE("https://logosmarcas.net/wp-content/uploads/2020/07/New-York-Giants-Logo.png"),IF(G2="WSH",IMAGE("https://logodownload.org/wp-content/uploads/2020/09/washington-commanders-logo.png"),IF(G2="DET",IMAGE("https://logos-world.net/wp-content/uploads/2020/05/Detroit-Lions-Logo-2017-Present.png"),IF(G2="GB",IMAGE("https://logodownload.org/wp-content/uploads/2020/07/green-bay-packers-logo-1.png"),IF(G2="MIN",IMAGE("https://1000logos.net/wp-content/uploads/2017/06/Minnesota-Vikings-Logo-1965.png"),IF(G2="CHI",IMAGE("https://logos-world.net/wp-content/uploads/2020/05/Chicago-Bears-logo.png"),IF(G2="TB",IMAGE("https://logodownload.org/wp-content/uploads/2020/09/tampa-bay-buccaneers-logo.png"),IF(G2="NO",IMAGE("https://1000logos.net/wp-content/uploads/2017/04/New-Orleans-Saints-Logo.png"),IF(G2="ATL",IMAGE("https://logodownload.org/wp-content/uploads/2020/07/atlanta-falcons-logo-0.png"),IF(G2="CAR",IMAGE("https://logos-download.com/wp-content/uploads/2018/02/Carolina_Panthers_logo_blue.png"),"")))))))))))))))))))))))))))))))) | I2: 21 | J2: 28 | K2: FALSE | L2: SEA | M2: =IF(L2="KC",IMAGE("https://logodownload.org/wp-content/uploads/2020/09/kansas-city-chiefs-logo.png"),IF(L2="LV",IMAGE("https://logodownload.org/wp-content/uploads/2020/09/las-vegas-raiders-logo-1-564x599.png"),IF(L2="DEN",IMAGE("https://logodownload.org/wp-content/uploads/2020/07/denver-broncos-logo-0.png"),IF(L2="LAC",IMAGE("https://logosmarcas.net/wp-content/uploads/2020/07/Los-Angeles-Chargers-logo.png"),IF(L2="BUF",IMAGE("https://logos-download.com/wp-content/uploads/2018/03/Buffalo_Bills_logo_blue.png"),IF(L2="MIA",IMAGE("https://logos-world.net/wp-content/uploads/2020/05/Miami-Dolphins-Logo.png"),IF(L2="NYJ",IMAGE("https://logos-world.net/wp-content/uploads/2020/07/New-York-Jets-Logo.png"),IF(L2="NE",IMAGE("https://purepng.com/public/uploads/large/new-england-patriots-logo-symbol-ucp.png"),IF(L2="BAL",IMAGE("https://1000logos.net/wp-content/uploads/2016/10/Baltimore-Ravens-Logo.png"),IF(L2="CLE",IMAGE("https://logos-world.net/wp-content/uploads/2020/05/Cleveland-Browns-Logo-2006-2014.png"),IF(L2="PIT",IMAGE("https://1000logos.net/wp-content/uploads/2017/06/Pittsburgh-Steelers-Logo.png"),IF(L2="CIN",IMAGE("https://logos-world.net/wp-content/uploads/2020/05/Cincinnati-Bengals-Logo.png"),IF(L2="HOU",IMAGE("https://cdn.wallpapersafari.com/15/25/Jnl2Yc.png"),IF(L2="JAX",IMAGE("https://1000logos.net/wp-content/uploads/2018/07/Jacksonville-Jaguars-Logo-1536x960.png"),IF(L2="IND",IMAGE("https://1000logos.net/wp-content/uploads/2016/12/Indianapolis-Colts-Logo-2048x1280.png"),IF(L2="TEN",IMAGE("https://img-s-msn-com.akamaized.net/tenant/amp/entityid/AA1YwbtK.img?w=720&h=720&m=6"),IF(L2="SF",IMAGE("https://logodownload.org/wp-content/uploads/2020/09/san-francisco-49ers-logo-2048x1220.png"),IF(L2="LAR",IMAGE("https://1000logos.net/wp-content/uploads/2018/07/Rams-Logo.png"),IF(L2="SEA",IMAGE("https://cdn.freebiesupply.com/images/large/2x/seattle-seahawks-logo-transparent.png"),IF(L2="AZ",IMAGE("https://logos-world.net/wp-content/uploads/2020/05/Arizona-Cardinals-Logo.png"),IF(L2="DAL",IMAGE("https://www.freepnglogos.com/uploads/dallas-cowboys-logo-22.png"),IF(L2="PHI",IMAGE("https://1000logos.net/wp-content/uploads/2017/05/Philadelphia-Eagles-Logo.png"),IF(L2="NYG",IMAGE("https://logosmarcas.net/wp-content/uploads/2020/07/New-York-Giants-Logo.png"),IF(L2="WSH",IMAGE("https://logodownload.org/wp-content/uploads/2020/09/washington-commanders-logo.png"),IF(L2="DET",IMAGE("https://logos-world.net/wp-content/uploads/2020/05/Detroit-Lions-Logo-2017-Present.png"),IF(L2="GB",IMAGE("https://logodownload.org/wp-content/uploads/2020/07/green-bay-packers-logo-1.png"),IF(L2="MIN",IMAGE("https://1000logos.net/wp-content/uploads/2017/06/Minnesota-Vikings-Logo-1965.png"),IF(L2="CHI",IMAGE("https://logos-world.net/wp-content/uploads/2020/05/Chicago-Bears-logo.png"),IF(L2="TB",IMAGE("https://logodownload.org/wp-content/uploads/2020/09/tampa-bay-buccaneers-logo.png"),IF(L2="NO",IMAGE("https://1000logos.net/wp-content/uploads/2017/04/New-Orleans-Saints-Logo.png"),IF(L2="ATL",IMAGE("https://logodownload.org/wp-content/uploads/2020/07/atlanta-falcons-logo-0.png"),IF(L2="CAR",IMAGE("https://logos-download.com/wp-content/uploads/2018/02/Carolina_Panthers_logo_blue.png"),"")))))))))))))))))))))))))))))))) | N2: 24 | O2: 27 | P2: FALSE | Q2: NE | R2: =IF(Q2="KC",IMAGE("https://logodownload.org/wp-content/uploads/2020/09/kansas-city-chiefs-logo.png"),IF(Q2="LV",IMAGE("https://logodownload.org/wp-content/uploads/2020/09/las-vegas-raiders-logo-1-564x599.png"),IF(Q2="DEN",IMAGE("https://logodownload.org/wp-content/uploads/2020/07/denver-broncos-logo-0.png"),IF(Q2="LAC",IMAGE("https://logosmarcas.net/wp-content/uploads/2020/07/Los-Angeles-Chargers-logo.png"),IF(Q2="BUF",IMAGE("https://logos-download.com/wp-content/uploads/2018/03/Buffalo_Bills_logo_blue.png"),IF(Q2="MIA",IMAGE("https://logos-world.net/wp-content/uploads/2020/05/Miami-Dolphins-Logo.png"),IF(Q2="NYJ",IMAGE("https://logos-world.net/wp-content/uploads/2020/07/New-York-Jets-Logo.png"),IF(Q2="NE",IMAGE("https://purepng.com/public/uploads/large/new-england-patriots-logo-symbol-ucp.png"),IF(Q2="BAL",IMAGE("https://1000logos.net/wp-content/uploads/2016/10/Baltimore-Ravens-Logo.png"),IF(Q2="CLE",IMAGE("https://logos-world.net/wp-content/uploads/2020/05/Cleveland-Browns-Logo-2006-2014.png"),IF(Q2="PIT",IMAGE("https://1000logos.net/wp-content/uploads/2017/06/Pittsburgh-Steelers-Logo.png"),IF(Q2="CIN",IMAGE("https://logos-world.net/wp-content/uploads/2020/05/Cincinnati-Bengals-Logo.png"),IF(Q2="HOU",IMAGE("https://cdn.wallpapersafari.com/15/25/Jnl2Yc.png"),IF(Q2="JAX",IMAGE("https://1000logos.net/wp-content/uploads/2018/07/Jacksonville-Jaguars-Logo-1536x960.png"),IF(Q2="IND",IMAGE("https://1000logos.net/wp-content/uploads/2016/12/Indianapolis-Colts-Logo-2048x1280.png"),IF(Q2="TEN",IMAGE("https://img-s-msn-com.akamaized.net/tenant/amp/entityid/AA1YwbtK.img?w=720&h=720&m=6"),IF(Q2="SF",IMAGE("https://logodownload.org/wp-content/uploads/2020/09/san-francisco-49ers-logo-2048x1220.png"),IF(Q2="LAR",IMAGE("https://1000logos.net/wp-content/uploads/2018/07/Rams-Logo.png"),IF(Q2="SEA",IMAGE("https://cdn.freebiesupply.com/images/large/2x/seattle-seahawks-logo-transparent.png"),IF(Q2="AZ",IMAGE("https://logos-world.net/wp-content/uploads/2020/05/Arizona-Cardinals-Logo.png"),IF(Q2="DAL",IMAGE("https://www.freepnglogos.com/uploads/dallas-cowboys-logo-22.png"),IF(Q2="PHI",IMAGE("https://1000logos.net/wp-content/uploads/2017/05/Philadelphia-Eagles-Logo.png"),IF(Q2="NYG",IMAGE("https://logosmarcas.net/wp-content/uploads/2020/07/New-York-Giants-Logo.png"),IF(Q2="WSH",IMAGE("https://logodownload.org/wp-content/uploads/2020/09/washington-commanders-logo.png"),IF(Q2="DET",IMAGE("https://logos-world.net/wp-content/uploads/2020/05/Detroit-Lions-Logo-2017-Present.png"),IF(Q2="GB",IMAGE("https://logodownload.org/wp-content/uploads/2020/07/green-bay-packers-logo-1.png"),IF(Q2="MIN",IMAGE("https://1000logos.net/wp-content/uploads/2017/06/Minnesota-Vikings-Logo-1965.png"),IF(Q2="CHI",IMAGE("https://logos-world.net/wp-content/uploads/2020/05/Chicago-Bears-logo.png"),IF(Q2="TB",IMAGE("https://logodownload.org/wp-content/uploads/2020/09/tampa-bay-buccaneers-logo.png"),IF(Q2="NO",IMAGE("https://1000logos.net/wp-content/uploads/2017/04/New-Orleans-Saints-Logo.png"),IF(Q2="ATL",IMAGE("https://logodownload.org/wp-content/uploads/2020/07/atlanta-falcons-logo-0.png"),IF(Q2="CAR",IMAGE("https://logos-download.com/wp-content/uploads/2018/02/Carolina_Panthers_logo_blue.png"),"")))))))))))))))))))))))))))))))) | S2: 24 | T2: 21 | U2: FALSE | V2: SEA | W2: =IF(V2="KC",IMAGE("https://logodownload.org/wp-content/uploads/2020/09/kansas-city-chiefs-logo.png"),IF(V2="LV",IMAGE("https://logodownload.org/wp-content/uploads/2020/09/las-vegas-raiders-logo-1-564x599.png"),IF(V2="DEN",IMAGE("https://logodownload.org/wp-content/uploads/2020/07/denver-broncos-logo-0.png"),IF(V2="LAC",IMAGE("https://logosmarcas.net/wp-content/uploads/2020/07/Los-Angeles-Chargers-logo.png"),IF(V2="BUF",IMAGE("https://logos-download.com/wp-content/uploads/2018/03/Buffalo_Bills_logo_blue.png"),IF(V2="MIA",IMAGE("https://logos-world.net/wp-content/uploads/2020/05/Miami-Dolphins-Logo.png"),IF(V2="NYJ",IMAGE("https://logos-world.net/wp-content/uploads/2020/07/New-York-Jets-Logo.png"),IF(V2="NE",IMAGE("https://purepng.com/public/uploads/large/new-england-patriots-logo-symbol-ucp.png"),IF(V2="BAL",IMAGE("https://1000logos.net/wp-content/uploads/2016/10/Baltimore-Ravens-Logo.png"),IF(V2="CLE",IMAGE("https://logos-world.net/wp-content/uploads/2020/05/Cleveland-Browns-Logo-2006-2014.png"),IF(V2="PIT",IMAGE("https://1000logos.net/wp-content/uploads/2017/06/Pittsburgh-Steelers-Logo.png"),IF(V2="CIN",IMAGE("https://logos-world.net/wp-content/uploads/2020/05/Cincinnati-Bengals-Logo.png"),IF(V2="HOU",IMAGE("https://cdn.wallpapersafari.com/15/25/Jnl2Yc.png"),IF(V2="JAX",IMAGE("https://1000logos.net/wp-content/uploads/2018/07/Jacksonville-Jaguars-Logo-1536x960.png"),IF(V2="IND",IMAGE("https://1000logos.net/wp-content/uploads/2016/12/Indianapolis-Colts-Logo-2048x1280.png"),IF(V2="TEN",IMAGE("https://img-s-msn-com.akamaized.net/tenant/amp/entityid/AA1YwbtK.img?w=720&h=720&m=6"),IF(V2="SF",IMAGE("https://logodownload.org/wp-content/uploads/2020/09/san-francisco-49ers-logo-2048x1220.png"),IF(V2="LAR",IMAGE("https://1000logos.net/wp-content/uploads/2018/07/Rams-Logo.png"),IF(V2="SEA",IMAGE("https://cdn.freebiesupply.com/images/large/2x/seattle-seahawks-logo-transparent.png"),IF(V2="AZ",IMAGE("https://logos-world.net/wp-content/uploads/2020/05/Arizona-Cardinals-Logo.png"),IF(V2="DAL",IMAGE("https://www.freepnglogos.com/uploads/dallas-cowboys-logo-22.png"),IF(V2="PHI",IMAGE("https://1000logos.net/wp-content/uploads/2017/05/Philadelphia-Eagles-Logo.png"),IF(V2="NYG",IMAGE("https://logosmarcas.net/wp-content/uploads/2020/07/New-York-Giants-Logo.png"),IF(V2="WSH",IMAGE("https://logodownload.org/wp-content/uploads/2020/09/washington-commanders-logo.png"),IF(V2="DET",IMAGE("https://logos-world.net/wp-content/uploads/2020/05/Detroit-Lions-Logo-2017-Present.png"),IF(V2="GB",IMAGE("https://logodownload.org/wp-content/uploads/2020/07/green-bay-packers-logo-1.png"),IF(V2="MIN",IMAGE("https://1000logos.net/wp-content/uploads/2017/06/Minnesota-Vikings-Logo-1965.png"),IF(V2="CHI",IMAGE("https://logos-world.net/wp-content/uploads/2020/05/Chicago-Bears-logo.png"),IF(V2="TB",IMAGE("https://logodownload.org/wp-content/uploads/2020/09/tampa-bay-buccaneers-logo.png"),IF(V2="NO",IMAGE("https://1000logos.net/wp-content/uploads/2017/04/New-Orleans-Saints-Logo.png"),IF(V2="ATL",IMAGE("https://logodownload.org/wp-content/uploads/2020/07/atlanta-falcons-logo-0.png"),IF(V2="CAR",IMAGE("https://logos-download.com/wp-content/uploads/2018/02/Carolina_Panthers_logo_blue.png"),"")))))))))))))))))))))))))))))))) | X2: 20 | Y2: 23 | Z2: FALSE | AA2: SEA | AB2: =IF(AA2="KC",IMAGE("https://logodownload.org/wp-content/uploads/2020/09/kansas-city-chiefs-logo.png"),IF(AA2="LV",IMAGE("https://logodownload.org/wp-content/uploads/2020/09/las-vegas-raiders-logo-1-564x599.png"),IF(AA2="DEN",IMAGE("https://logodownload.org/wp-content/uploads/2020/07/denver-broncos-logo-0.png"),IF(AA2="LAC",IMAGE("https://logosmarcas.net/wp-content/uploads/2020/07/Los-Angeles-Chargers-logo.png"),IF(AA2="BUF",IMAGE("https://logos-download.com/wp-content/uploads/2018/03/Buffalo_Bills_logo_blue.png"),IF(AA2="MIA",IMAGE("https://logos-world.net/wp-content/uploads/2020/05/Miami-Dolphins-Logo.png"),IF(AA2="NYJ",IMAGE("https://logos-world.net/wp-content/uploads/2020/07/New-York-Jets-Logo.png"),IF(AA2="NE",IMAGE("https://purepng.com/public/uploads/large/new-england-patriots-logo-symbol-ucp.png"),IF(AA2="BAL",IMAGE("https://1000logos.net/wp-content/uploads/2016/10/Baltimore-Ravens-Logo.png"),IF(AA2="CLE",IMAGE("https://logos-world.net/wp-content/uploads/2020/05/Cleveland-Browns-Logo-2006-2014.png"),IF(AA2="PIT",IMAGE("https://1000logos.net/wp-content/uploads/2017/06/Pittsburgh-Steelers-Logo.png"),IF(AA2="CIN",IMAGE("https://logos-world.net/wp-content/uploads/2020/05/Cincinnati-Bengals-Logo.png"),IF(AA2="HOU",IMAGE("https://cdn.wallpapersafari.com/15/25/Jnl2Yc.png"),IF(AA2="JAX",IMAGE("https://1000logos.net/wp-content/uploads/2018/07/Jacksonville-Jaguars-Logo-1536x960.png"),IF(AA2="IND",IMAGE("https://1000logos.net/wp-content/uploads/2016/12/Indianapolis-Colts-Logo-2048x1280.png"),IF(AA2="TEN",IMAGE("https://img-s-msn-com.akamaized.net/tenant/amp/entityid/AA1YwbtK.img?w=720&h=720&m=6"),IF(AA2="SF",IMAGE("https://logodownload.org/wp-content/uploads/2020/09/san-francisco-49ers-logo-2048x1220.png"),IF(AA2="LAR",IMAGE("https://1000logos.net/wp-content/uploads/2018/07/Rams-Logo.png"),IF(AA2="SEA",IMAGE("https://cdn.freebiesupply.com/images/large/2x/seattle-seahawks-logo-transparent.png"),IF(AA2="AZ",IMAGE("https://logos-world.net/wp-content/uploads/2020/05/Arizona-Cardinals-Logo.png"),IF(AA2="DAL",IMAGE("https://www.freepnglogos.com/uploads/dallas-cowboys-logo-22.png"),IF(AA2="PHI",IMAGE("https://1000logos.net/wp-content/uploads/2017/05/Philadelphia-Eagles-Logo.png"),IF(AA2="NYG",IMAGE("https://logosmarcas.net/wp-content/uploads/2020/07/New-York-Giants-Logo.png"),IF(AA2="WSH",IMAGE("https://logodownload.org/wp-content/uploads/2020/09/washington-commanders-logo.png"),IF(AA2="DET",IMAGE("https://logos-world.net/wp-content/uploads/2020/05/Detroit-Lions-Logo-2017-Present.png"),IF(AA2="GB",IMAGE("https://logodownload.org/wp-content/uploads/2020/07/green-bay-packers-logo-1.png"),IF(AA2="MIN",IMAGE("https://1000logos.net/wp-content/uploads/2017/06/Minnesota-Vikings-Logo-1965.png"),IF(AA2="CHI",IMAGE("https://logos-world.net/wp-content/uploads/2020/05/Chicago-Bears-logo.png"),IF(AA2="TB",IMAGE("https://logodownload.org/wp-content/uploads/2020/09/tampa-bay-buccaneers-logo.png"),IF(AA2="NO",IMAGE("https://1000logos.net/wp-content/uploads/2017/04/New-Orleans-Saints-Logo.png"),IF(AA2="ATL",IMAGE("https://logodownload.org/wp-content/uploads/2020/07/atlanta-falcons-logo-0.png"),IF(AA2="CAR",IMAGE("https://logos-download.com/wp-content/uploads/2018/02/Carolina_Panthers_logo_blue.png"),"")))))))))))))))))))))))))))))))) | AC2: 17 | AD2: 21 | AE2: FALSE | AF2: NE | AG2: =IF(AF2="KC",IMAGE("https://logodownload.org/wp-content/uploads/2020/09/kansas-city-chiefs-logo.png"),IF(AF2="LV",IMAGE("https://logodownload.org/wp-content/uploads/2020/09/las-vegas-raiders-logo-1-564x599.png"),IF(AF2="DEN",IMAGE("https://logodownload.org/wp-content/uploads/2020/07/denver-broncos-logo-0.png"),IF(AF2="LAC",IMAGE("https://logosmarcas.net/wp-content/uploads/2020/07/Los-Angeles-Chargers-logo.png"),IF(AF2="BUF",IMAGE("https://logos-download.com/wp-content/uploads/2018/03/Buffalo_Bills_logo_blue.png"),IF(AF2="MIA",IMAGE("https://logos-world.net/wp-content/uploads/2020/05/Miami-Dolphins-Logo.png"),IF(AF2="NYJ",IMAGE("https://logos-world.net/wp-content/uploads/2020/07/New-York-Jets-Logo.png"),IF(AF2="NE",IMAGE("https://purepng.com/public/uploads/large/new-england-patriots-logo-symbol-ucp.png"),IF(AF2="BAL",IMAGE("https://1000logos.net/wp-content/uploads/2016/10/Baltimore-Ravens-Logo.png"),IF(AF2="CLE",IMAGE("https://logos-world.net/wp-content/uploads/2020/05/Cleveland-Browns-Logo-2006-2014.png"),IF(AF2="PIT",IMAGE("https://1000logos.net/wp-content/uploads/2017/06/Pittsburgh-Steelers-Logo.png"),IF(AF2="CIN",IMAGE("https://logos-world.net/wp-content/uploads/2020/05/Cincinnati-Bengals-Logo.png"),IF(AF2="HOU",IMAGE("https://cdn.wallpapersafari.com/15/25/Jnl2Yc.png"),IF(AF2="JAX",IMAGE("https://1000logos.net/wp-content/uploads/2018/07/Jacksonville-Jaguars-Logo-1536x960.png"),IF(AF2="IND",IMAGE("https://1000logos.net/wp-content/uploads/2016/12/Indianapolis-Colts-Logo-2048x1280.png"),IF(AF2="TEN",IMAGE("https://img-s-msn-com.akamaized.net/tenant/amp/entityid/AA1YwbtK.img?w=720&h=720&m=6"),IF(AF2="SF",IMAGE("https://logodownload.org/wp-content/uploads/2020/09/san-francisco-49ers-logo-2048x1220.png"),IF(AF2="LAR",IMAGE("https://1000logos.net/wp-content/uploads/2018/07/Rams-Logo.png"),IF(AF2="SEA",IMAGE("https://cdn.freebiesupply.com/images/large/2x/seattle-seahawks-logo-transparent.png"),IF(AF2="AZ",IMAGE("https://logos-world.net/wp-content/uploads/2020/05/Arizona-Cardinals-Logo.png"),IF(AF2="DAL",IMAGE("https://www.freepnglogos.com/uploads/dallas-cowboys-logo-22.png"),IF(AF2="PHI",IMAGE("https://1000logos.net/wp-content/uploads/2017/05/Philadelphia-Eagles-Logo.png"),IF(AF2="NYG",IMAGE("https://logosmarcas.net/wp-content/uploads/2020/07/New-York-Giants-Logo.png"),IF(AF2="WSH",IMAGE("https://logodownload.org/wp-content/uploads/2020/09/washington-commanders-logo.png"),IF(AF2="DET",IMAGE("https://logos-world.net/wp-content/uploads/2020/05/Detroit-Lions-Logo-2017-Present.png"),IF(AF2="GB",IMAGE("https://logodownload.org/wp-content/uploads/2020/07/green-bay-packers-logo-1.png"),IF(AF2="MIN",IMAGE("https://1000logos.net/wp-content/uploads/2017/06/Minnesota-Vikings-Logo-1965.png"),IF(AF2="CHI",IMAGE("https://logos-world.net/wp-content/uploads/2020/05/Chicago-Bears-logo.png"),IF(AF2="TB",IMAGE("https://logodownload.org/wp-content/uploads/2020/09/tampa-bay-buccaneers-logo.png"),IF(AF2="NO",IMAGE("https://1000logos.net/wp-content/uploads/2017/04/New-Orleans-Saints-Logo.png"),IF(AF2="ATL",IMAGE("https://logodownload.org/wp-content/uploads/2020/07/atlanta-falcons-logo-0.png"),IF(AF2="CAR",IMAGE("https://logos-download.com/wp-content/uploads/2018/02/Carolina_Panthers_logo_blue.png"),"")))))))))))))))))))))))))))))))) | AH2: 23 | AI2: 20 | AJ2: FALSE | AK2: SEA | AL2: =IF(AK2="KC",IMAGE("https://logodownload.org/wp-content/uploads/2020/09/kansas-city-chiefs-logo.png"),IF(AK2="LV",IMAGE("https://logodownload.org/wp-content/uploads/2020/09/las-vegas-raiders-logo-1-564x599.png"),IF(AK2="DEN",IMAGE("https://logodownload.org/wp-content/uploads/2020/07/denver-broncos-logo-0.png"),IF(AK2="LAC",IMAGE("https://logosmarcas.net/wp-content/uploads/2020/07/Los-Angeles-Chargers-logo.png"),IF(AK2="BUF",IMAGE("https://logos-download.com/wp-content/uploads/2018/03/Buffalo_Bills_logo_blue.png"),IF(AK2="MIA",IMAGE("https://logos-world.net/wp-content/uploads/2020/05/Miami-Dolphins-Logo.png"),IF(AK2="NYJ",IMAGE("https://logos-world.net/wp-content/uploads/2020/07/New-York-Jets-Logo.png"),IF(AK2="NE",IMAGE("https://purepng.com/public/uploads/large/new-england-patriots-logo-symbol-ucp.png"),IF(AK2="BAL",IMAGE("https://1000logos.net/wp-content/uploads/2016/10/Baltimore-Ravens-Logo.png"),IF(AK2="CLE",IMAGE("https://logos-world.net/wp-content/uploads/2020/05/Cleveland-Browns-Logo-2006-2014.png"),IF(AK2="PIT",IMAGE("https://1000logos.net/wp-content/uploads/2017/06/Pittsburgh-Steelers-Logo.png"),IF(AK2="CIN",IMAGE("https://logos-world.net/wp-content/uploads/2020/05/Cincinnati-Bengals-Logo.png"),IF(AK2="HOU",IMAGE("https://cdn.wallpapersafari.com/15/25/Jnl2Yc.png"),IF(AK2="JAX",IMAGE("https://1000logos.net/wp-content/uploads/2018/07/Jacksonville-Jaguars-Logo-1536x960.png"),IF(AK2="IND",IMAGE("https://1000logos.net/wp-content/uploads/2016/12/Indianapolis-Colts-Logo-2048x1280.png"),IF(AK2="TEN",IMAGE("https://img-s-msn-com.akamaized.net/tenant/amp/entityid/AA1YwbtK.img?w=720&h=720&m=6"),IF(AK2="SF",IMAGE("https://logodownload.org/wp-content/uploads/2020/09/san-francisco-49ers-logo-2048x1220.png"),IF(AK2="LAR",IMAGE("https://1000logos.net/wp-content/uploads/2018/07/Rams-Logo.png"),IF(AK2="SEA",IMAGE("https://cdn.freebiesupply.com/images/large/2x/seattle-seahawks-logo-transparent.png"),IF(AK2="AZ",IMAGE("https://logos-world.net/wp-content/uploads/2020/05/Arizona-Cardinals-Logo.png"),IF(AK2="DAL",IMAGE("https://www.freepnglogos.com/uploads/dallas-cowboys-logo-22.png"),IF(AK2="PHI",IMAGE("https://1000logos.net/wp-content/uploads/2017/05/Philadelphia-Eagles-Logo.png"),IF(AK2="NYG",IMAGE("https://logosmarcas.net/wp-content/uploads/2020/07/New-York-Giants-Logo.png"),IF(AK2="WSH",IMAGE("https://logodownload.org/wp-content/uploads/2020/09/washington-commanders-logo.png"),IF(AK2="DET",IMAGE("https://logos-world.net/wp-content/uploads/2020/05/Detroit-Lions-Logo-2017-Present.png"),IF(AK2="GB",IMAGE("https://logodownload.org/wp-content/uploads/2020/07/green-bay-packers-logo-1.png"),IF(AK2="MIN",IMAGE("https://1000logos.net/wp-content/uploads/2017/06/Minnesota-Vikings-Logo-1965.png"),IF(AK2="CHI",IMAGE("https://logos-world.net/wp-content/uploads/2020/05/Chicago-Bears-logo.png"),IF(AK2="TB",IMAGE("https://logodownload.org/wp-content/uploads/2020/09/tampa-bay-buccaneers-logo.png"),IF(AK2="NO",IMAGE("https://1000logos.net/wp-content/uploads/2017/04/New-Orleans-Saints-Logo.png"),IF(AK2="ATL",IMAGE("https://logodownload.org/wp-content/uploads/2020/07/atlanta-falcons-logo-0.png"),IF(AK2="CAR",IMAGE("https://logos-download.com/wp-content/uploads/2018/02/Carolina_Panthers_logo_blue.png"),"")))))))))))))))))))))))))))))))) | AM2: 10 | AN2: 14 | AO2: FALSE | AP2: SEA | AQ2: =IF(AP2="KC",IMAGE("https://logodownload.org/wp-content/uploads/2020/09/kansas-city-chiefs-logo.png"),IF(AP2="LV",IMAGE("https://logodownload.org/wp-content/uploads/2020/09/las-vegas-raiders-logo-1-564x599.png"),IF(AP2="DEN",IMAGE("https://logodownload.org/wp-content/uploads/2020/07/denver-broncos-logo-0.png"),IF(AP2="LAC",IMAGE("https://logosmarcas.net/wp-content/uploads/2020/07/Los-Angeles-Chargers-logo.png"),IF(AP2="BUF",IMAGE("https://logos-download.com/wp-content/uploads/2018/03/Buffalo_Bills_logo_blue.png"),IF(AP2="MIA",IMAGE("https://logos-world.net/wp-content/uploads/2020/05/Miami-Dolphins-Logo.png"),IF(AP2="NYJ",IMAGE("https://logos-world.net/wp-content/uploads/2020/07/New-York-Jets-Logo.png"),IF(AP2="NE",IMAGE("https://purepng.com/public/uploads/large/new-england-patriots-logo-symbol-ucp.png"),IF(AP2="BAL",IMAGE("https://1000logos.net/wp-content/uploads/2016/10/Baltimore-Ravens-Logo.png"),IF(AP2="CLE",IMAGE("https://logos-world.net/wp-content/uploads/2020/05/Cleveland-Browns-Logo-2006-2014.png"),IF(AP2="PIT",IMAGE("https://1000logos.net/wp-content/uploads/2017/06/Pittsburgh-Steelers-Logo.png"),IF(AP2="CIN",IMAGE("https://logos-world.net/wp-content/uploads/2020/05/Cincinnati-Bengals-Logo.png"),IF(AP2="HOU",IMAGE("https://cdn.wallpapersafari.com/15/25/Jnl2Yc.png"),IF(AP2="JAX",IMAGE("https://1000logos.net/wp-content/uploads/2018/07/Jacksonville-Jaguars-Logo-1536x960.png"),IF(AP2="IND",IMAGE("https://1000logos.net/wp-content/uploads/2016/12/Indianapolis-Colts-Logo-2048x1280.png"),IF(AP2="TEN",IMAGE("https://img-s-msn-com.akamaized.net/tenant/amp/entityid/AA1YwbtK.img?w=720&h=720&m=6"),IF(AP2="SF",IMAGE("https://logodownload.org/wp-content/uploads/2020/09/san-francisco-49ers-logo-2048x1220.png"),IF(AP2="LAR",IMAGE("https://1000logos.net/wp-content/uploads/2018/07/Rams-Logo.png"),IF(AP2="SEA",IMAGE("https://cdn.freebiesupply.com/images/large/2x/seattle-seahawks-logo-transparent.png"),IF(AP2="AZ",IMAGE("https://logos-world.net/wp-content/uploads/2020/05/Arizona-Cardinals-Logo.png"),IF(AP2="DAL",IMAGE("https://www.freepnglogos.com/uploads/dallas-cowboys-logo-22.png"),IF(AP2="PHI",IMAGE("https://1000logos.net/wp-content/uploads/2017/05/Philadelphia-Eagles-Logo.png"),IF(AP2="NYG",IMAGE("https://logosmarcas.net/wp-content/uploads/2020/07/New-York-Giants-Logo.png"),IF(AP2="WSH",IMAGE("https://logodownload.org/wp-content/uploads/2020/09/washington-commanders-logo.png"),IF(AP2="DET",IMAGE("https://logos-world.net/wp-content/uploads/2020/05/Detroit-Lions-Logo-2017-Present.png"),IF(AP2="GB",IMAGE("https://logodownload.org/wp-content/uploads/2020/07/green-bay-packers-logo-1.png"),IF(AP2="MIN",IMAGE("https://1000logos.net/wp-content/uploads/2017/06/Minnesota-Vikings-Logo-1965.png"),IF(AP2="CHI",IMAGE("https://logos-world.net/wp-content/uploads/2020/05/Chicago-Bears-logo.png"),IF(AP2="TB",IMAGE("https://logodownload.org/wp-content/uploads/2020/09/tampa-bay-buccaneers-logo.png"),IF(AP2="NO",IMAGE("https://1000logos.net/wp-content/uploads/2017/04/New-Orleans-Saints-Logo.png"),IF(AP2="ATL",IMAGE("https://logodownload.org/wp-content/uploads/2020/07/atlanta-falcons-logo-0.png"),IF(AP2="CAR",IMAGE("https://logos-download.com/wp-content/uploads/2018/02/Carolina_Panthers_logo_blue.png"),"")))))))))))))))))))))))))))))))) | AR2: 17 | AS2: 24 | AT2: FALSE | AU2: NE | AV2: =IF(AU2="KC",IMAGE("https://logodownload.org/wp-content/uploads/2020/09/kansas-city-chiefs-logo.png"),IF(AU2="LV",IMAGE("https://logodownload.org/wp-content/uploads/2020/09/las-vegas-raiders-logo-1-564x599.png"),IF(AU2="DEN",IMAGE("https://logodownload.org/wp-content/uploads/2020/07/denver-broncos-logo-0.png"),IF(AU2="LAC",IMAGE("https://logosmarcas.net/wp-content/uploads/2020/07/Los-Angeles-Chargers-logo.png"),IF(AU2="BUF",IMAGE("https://logos-download.com/wp-content/uploads/2018/03/Buffalo_Bills_logo_blue.png"),IF(AU2="MIA",IMAGE("https://logos-world.net/wp-content/uploads/2020/05/Miami-Dolphins-Logo.png"),IF(AU2="NYJ",IMAGE("https://logos-world.net/wp-content/uploads/2020/07/New-York-Jets-Logo.png"),IF(AU2="NE",IMAGE("https://purepng.com/public/uploads/large/new-england-patriots-logo-symbol-ucp.png"),IF(AU2="BAL",IMAGE("https://1000logos.net/wp-content/uploads/2016/10/Baltimore-Ravens-Logo.png"),IF(AU2="CLE",IMAGE("https://logos-world.net/wp-content/uploads/2020/05/Cleveland-Browns-Logo-2006-2014.png"),IF(AU2="PIT",IMAGE("https://1000logos.net/wp-content/uploads/2017/06/Pittsburgh-Steelers-Logo.png"),IF(AU2="CIN",IMAGE("https://logos-world.net/wp-content/uploads/2020/05/Cincinnati-Bengals-Logo.png"),IF(AU2="HOU",IMAGE("https://cdn.wallpapersafari.com/15/25/Jnl2Yc.png"),IF(AU2="JAX",IMAGE("https://1000logos.net/wp-content/uploads/2018/07/Jacksonville-Jaguars-Logo-1536x960.png"),IF(AU2="IND",IMAGE("https://1000logos.net/wp-content/uploads/2016/12/Indianapolis-Colts-Logo-2048x1280.png"),IF(AU2="TEN",IMAGE("https://img-s-msn-com.akamaized.net/tenant/amp/entityid/AA1YwbtK.img?w=720&h=720&m=6"),IF(AU2="SF",IMAGE("https://logodownload.org/wp-content/uploads/2020/09/san-francisco-49ers-logo-2048x1220.png"),IF(AU2="LAR",IMAGE("https://1000logos.net/wp-content/uploads/2018/07/Rams-Logo.png"),IF(AU2="SEA",IMAGE("https://cdn.freebiesupply.com/images/large/2x/seattle-seahawks-logo-transparent.png"),IF(AU2="AZ",IMAGE("https://logos-world.net/wp-content/uploads/2020/05/Arizona-Cardinals-Logo.png"),IF(AU2="DAL",IMAGE("https://www.freepnglogos.com/uploads/dallas-cowboys-logo-22.png"),IF(AU2="PHI",IMAGE("https://1000logos.net/wp-content/uploads/2017/05/Philadelphia-Eagles-Logo.png"),IF(AU2="NYG",IMAGE("https://logosmarcas.net/wp-content/uploads/2020/07/New-York-Giants-Logo.png"),IF(AU2="WSH",IMAGE("https://logodownload.org/wp-content/uploads/2020/09/washington-commanders-logo.png"),IF(AU2="DET",IMAGE("https://logos-world.net/wp-content/uploads/2020/05/Detroit-Lions-Logo-2017-Present.png"),IF(AU2="GB",IMAGE("https://logodownload.org/wp-content/uploads/2020/07/green-bay-packers-logo-1.png"),IF(AU2="MIN",IMAGE("https://1000logos.net/wp-content/uploads/2017/06/Minnesota-Vikings-Logo-1965.png"),IF(AU2="CHI",IMAGE("https://logos-world.net/wp-content/uploads/2020/05/Chicago-Bears-logo.png"),IF(AU2="TB",IMAGE("https://logodownload.org/wp-content/uploads/2020/09/tampa-bay-buccaneers-logo.png"),IF(AU2="NO",IMAGE("https://1000logos.net/wp-content/uploads/2017/04/New-Orleans-Saints-Logo.png"),IF(AU2="ATL",IMAGE("https://logodownload.org/wp-content/uploads/2020/07/atlanta-falcons-logo-0.png"),IF(AU2="CAR",IMAGE("https://logos-download.com/wp-content/uploads/2018/02/Carolina_Panthers_logo_blue.png"),"")))))))))))))))))))))))))))))))) | AW2: 23 | AX2: 20 | AY2: FALSE | AZ2: SEA | BA2: =IF(AZ2="KC",IMAGE("https://logodownload.org/wp-content/uploads/2020/09/kansas-city-chiefs-logo.png"),IF(AZ2="LV",IMAGE("https://logodownload.org/wp-content/uploads/2020/09/las-vegas-raiders-logo-1-564x599.png"),IF(AZ2="DEN",IMAGE("https://logodownload.org/wp-content/uploads/2020/07/denver-broncos-logo-0.png"),IF(AZ2="LAC",IMAGE("https://logosmarcas.net/wp-content/uploads/2020/07/Los-Angeles-Chargers-logo.png"),IF(AZ2="BUF",IMAGE("https://logos-download.com/wp-content/uploads/2018/03/Buffalo_Bills_logo_blue.png"),IF(AZ2="MIA",IMAGE("https://logos-world.net/wp-content/uploads/2020/05/Miami-Dolphins-Logo.png"),IF(AZ2="NYJ",IMAGE("https://logos-world.net/wp-content/uploads/2020/07/New-York-Jets-Logo.png"),IF(AZ2="NE",IMAGE("https://purepng.com/public/uploads/large/new-england-patriots-logo-symbol-ucp.png"),IF(AZ2="BAL",IMAGE("https://1000logos.net/wp-content/uploads/2016/10/Baltimore-Ravens-Logo.png"),IF(AZ2="CLE",IMAGE("https://logos-world.net/wp-content/uploads/2020/05/Cleveland-Browns-Logo-2006-2014.png"),IF(AZ2="PIT",IMAGE("https://1000logos.net/wp-content/uploads/2017/06/Pittsburgh-Steelers-Logo.png"),IF(AZ2="CIN",IMAGE("https://logos-world.net/wp-content/uploads/2020/05/Cincinnati-Bengals-Logo.png"),IF(AZ2="HOU",IMAGE("https://cdn.wallpapersafari.com/15/25/Jnl2Yc.png"),IF(AZ2="JAX",IMAGE("https://1000logos.net/wp-content/uploads/2018/07/Jacksonville-Jaguars-Logo-1536x960.png"),IF(AZ2="IND",IMAGE("https://1000logos.net/wp-content/uploads/2016/12/Indianapolis-Colts-Logo-2048x1280.png"),IF(AZ2="TEN",IMAGE("https://img-s-msn-com.akamaized.net/tenant/amp/entityid/AA1YwbtK.img?w=720&h=720&m=6"),IF(AZ2="SF",IMAGE("https://logodownload.org/wp-content/uploads/2020/09/san-francisco-49ers-logo-2048x1220.png"),IF(AZ2="LAR",IMAGE("https://1000logos.net/wp-content/uploads/2018/07/Rams-Logo.png"),IF(AZ2="SEA",IMAGE("https://cdn.freebiesupply.com/images/large/2x/seattle-seahawks-logo-transparent.png"),IF(AZ2="AZ",IMAGE("https://logos-world.net/wp-content/uploads/2020/05/Arizona-Cardinals-Logo.png"),IF(AZ2="DAL",IMAGE("https://www.freepnglogos.com/uploads/dallas-cowboys-logo-22.png"),IF(AZ2="PHI",IMAGE("https://1000logos.net/wp-content/uploads/2017/05/Philadelphia-Eagles-Logo.png"),IF(AZ2="NYG",IMAGE("https://logosmarcas.net/wp-content/uploads/2020/07/New-York-Giants-Logo.png"),IF(AZ2="WSH",IMAGE("https://logodownload.org/wp-content/uploads/2020/09/washington-commanders-logo.png"),IF(AZ2="DET",IMAGE("https://logos-world.net/wp-content/uploads/2020/05/Detroit-Lions-Logo-2017-Present.png"),IF(AZ2="GB",IMAGE("https://logodownload.org/wp-content/uploads/2020/07/green-bay-packers-logo-1.png"),IF(AZ2="MIN",IMAGE("https://1000logos.net/wp-content/uploads/2017/06/Minnesota-Vikings-Logo-1965.png"),IF(AZ2="CHI",IMAGE("https://logos-world.net/wp-content/uploads/2020/05/Chicago-Bears-logo.png"),IF(AZ2="TB",IMAGE("https://logodownload.org/wp-content/uploads/2020/09/tampa-bay-buccaneers-logo.png"),IF(AZ2="NO",IMAGE("https://1000logos.net/wp-content/uploads/2017/04/New-Orleans-Saints-Logo.png"),IF(AZ2="ATL",IMAGE("https://logodownload.org/wp-content/uploads/2020/07/atlanta-falcons-logo-0.png"),IF(AZ2="CAR",IMAGE("https://logos-download.com/wp-content/uploads/2018/02/Carolina_Panthers_logo_blue.png"),"")))))))))))))))))))))))))))))))) | BB2: 20 | BC2: 23 | BD2: FALSE | BE2: SEA | BF2: =IF(BE2="KC",IMAGE("https://logodownload.org/wp-content/uploads/2020/09/kansas-city-chiefs-logo.png"),IF(BE2="LV",IMAGE("https://logodownload.org/wp-content/uploads/2020/09/las-vegas-raiders-logo-1-564x599.png"),IF(BE2="DEN",IMAGE("https://logodownload.org/wp-content/uploads/2020/07/denver-broncos-logo-0.png"),IF(BE2="LAC",IMAGE("https://logosmarcas.net/wp-content/uploads/2020/07/Los-Angeles-Chargers-logo.png"),IF(BE2="BUF",IMAGE("https://logos-download.com/wp-content/uploads/2018/03/Buffalo_Bills_logo_blue.png"),IF(BE2="MIA",IMAGE("https://logos-world.net/wp-content/uploads/2020/05/Miami-Dolphins-Logo.png"),IF(BE2="NYJ",IMAGE("https://logos-world.net/wp-content/uploads/2020/07/New-York-Jets-Logo.png"),IF(BE2="NE",IMAGE("https://purepng.com/public/uploads/large/new-england-patriots-logo-symbol-ucp.png"),IF(BE2="BAL",IMAGE("https://1000logos.net/wp-content/uploads/2016/10/Baltimore-Ravens-Logo.png"),IF(BE2="CLE",IMAGE("https://logos-world.net/wp-content/uploads/2020/05/Cleveland-Browns-Logo-2006-2014.png"),IF(BE2="PIT",IMAGE("https://1000logos.net/wp-content/uploads/2017/06/Pittsburgh-Steelers-Logo.png"),IF(BE2="CIN",IMAGE("https://logos-world.net/wp-content/uploads/2020/05/Cincinnati-Bengals-Logo.png"),IF(BE2="HOU",IMAGE("https://cdn.wallpapersafari.com/15/25/Jnl2Yc.png"),IF(BE2="JAX",IMAGE("https://1000logos.net/wp-content/uploads/2018/07/Jacksonville-Jaguars-Logo-1536x960.png"),IF(BE2="IND",IMAGE("https://1000logos.net/wp-content/uploads/2016/12/Indianapolis-Colts-Logo-2048x1280.png"),IF(BE2="TEN",IMAGE("https://img-s-msn-com.akamaized.net/tenant/amp/entityid/AA1YwbtK.img?w=720&h=720&m=6"),IF(BE2="SF",IMAGE("https://logodownload.org/wp-content/uploads/2020/09/san-francisco-49ers-logo-2048x1220.png"),IF(BE2="LAR",IMAGE("https://1000logos.net/wp-content/uploads/2018/07/Rams-Logo.png"),IF(BE2="SEA",IMAGE("https://cdn.freebiesupply.com/images/large/2x/seattle-seahawks-logo-transparent.png"),IF(BE2="AZ",IMAGE("https://logos-world.net/wp-content/uploads/2020/05/Arizona-Cardinals-Logo.png"),IF(BE2="DAL",IMAGE("https://www.freepnglogos.com/uploads/dallas-cowboys-logo-22.png"),IF(BE2="PHI",IMAGE("https://1000logos.net/wp-content/uploads/2017/05/Philadelphia-Eagles-Logo.png"),IF(BE2="NYG",IMAGE("https://logosmarcas.net/wp-content/uploads/2020/07/New-York-Giants-Logo.png"),IF(BE2="WSH",IMAGE("https://logodownload.org/wp-content/uploads/2020/09/washington-commanders-logo.png"),IF(BE2="DET",IMAGE("https://logos-world.net/wp-content/uploads/2020/05/Detroit-Lions-Logo-2017-Present.png"),IF(BE2="GB",IMAGE("https://logodownload.org/wp-content/uploads/2020/07/green-bay-packers-logo-1.png"),IF(BE2="MIN",IMAGE("https://1000logos.net/wp-content/uploads/2017/06/Minnesota-Vikings-Logo-1965.png"),IF(BE2="CHI",IMAGE("https://logos-world.net/wp-content/uploads/2020/05/Chicago-Bears-logo.png"),IF(BE2="TB",IMAGE("https://logodownload.org/wp-content/uploads/2020/09/tampa-bay-buccaneers-logo.png"),IF(BE2="NO",IMAGE("https://1000logos.net/wp-content/uploads/2017/04/New-Orleans-Saints-Logo.png"),IF(BE2="ATL",IMAGE("https://logodownload.org/wp-content/uploads/2020/07/atlanta-falcons-logo-0.png"),IF(BE2="CAR",IMAGE("https://logos-download.com/wp-content/uploads/2018/02/Carolina_Panthers_logo_blue.png"),"")))))))))))))))))))))))))))))))) | BG2: 17 | BH2: 24 | BI2: FALSE | BJ2: SEA | BK2: =IF(BJ2="KC",IMAGE("https://logodownload.org/wp-content/uploads/2020/09/kansas-city-chiefs-logo.png"),IF(BJ2="LV",IMAGE("https://logodownload.org/wp-content/uploads/2020/09/las-vegas-raiders-logo-1-564x599.png"),IF(BJ2="DEN",IMAGE("https://logodownload.org/wp-content/uploads/2020/07/denver-broncos-logo-0.png"),IF(BJ2="LAC",IMAGE("https://logosmarcas.net/wp-content/uploads/2020/07/Los-Angeles-Chargers-logo.png"),IF(BJ2="BUF",IMAGE("https://logos-download.com/wp-content/uploads/2018/03/Buffalo_Bills_logo_blue.png"),IF(BJ2="MIA",IMAGE("https://logos-world.net/wp-content/uploads/2020/05/Miami-Dolphins-Logo.png"),IF(BJ2="NYJ",IMAGE("https://logos-world.net/wp-content/uploads/2020/07/New-York-Jets-Logo.png"),IF(BJ2="NE",IMAGE("https://purepng.com/public/uploads/large/new-england-patriots-logo-symbol-ucp.png"),IF(BJ2="BAL",IMAGE("https://1000logos.net/wp-content/uploads/2016/10/Baltimore-Ravens-Logo.png"),IF(BJ2="CLE",IMAGE("https://logos-world.net/wp-content/uploads/2020/05/Cleveland-Browns-Logo-2006-2014.png"),IF(BJ2="PIT",IMAGE("https://1000logos.net/wp-content/uploads/2017/06/Pittsburgh-Steelers-Logo.png"),IF(BJ2="CIN",IMAGE("https://logos-world.net/wp-content/uploads/2020/05/Cincinnati-Bengals-Logo.png"),IF(BJ2="HOU",IMAGE("https://cdn.wallpapersafari.com/15/25/Jnl2Yc.png"),IF(BJ2="JAX",IMAGE("https://1000logos.net/wp-content/uploads/2018/07/Jacksonville-Jaguars-Logo-1536x960.png"),IF(BJ2="IND",IMAGE("https://1000logos.net/wp-content/uploads/2016/12/Indianapolis-Colts-Logo-2048x1280.png"),IF(BJ2="TEN",IMAGE("https://img-s-msn-com.akamaized.net/tenant/amp/entityid/AA1YwbtK.img?w=720&h=720&m=6"),IF(BJ2="SF",IMAGE("https://logodownload.org/wp-content/uploads/2020/09/san-francisco-49ers-logo-2048x1220.png"),IF(BJ2="LAR",IMAGE("https://1000logos.net/wp-content/uploads/2018/07/Rams-Logo.png"),IF(BJ2="SEA",IMAGE("https://cdn.freebiesupply.com/images/large/2x/seattle-seahawks-logo-transparent.png"),IF(BJ2="AZ",IMAGE("https://logos-world.net/wp-content/uploads/2020/05/Arizona-Cardinals-Logo.png"),IF(BJ2="DAL",IMAGE("https://www.freepnglogos.com/uploads/dallas-cowboys-logo-22.png"),IF(BJ2="PHI",IMAGE("https://1000logos.net/wp-content/uploads/2017/05/Philadelphia-Eagles-Logo.png"),IF(BJ2="NYG",IMAGE("https://logosmarcas.net/wp-content/uploads/2020/07/New-York-Giants-Logo.png"),IF(BJ2="WSH",IMAGE("https://logodownload.org/wp-content/uploads/2020/09/washington-commanders-logo.png"),IF(BJ2="DET",IMAGE("https://logos-world.net/wp-content/uploads/2020/05/Detroit-Lions-Logo-2017-Present.png"),IF(BJ2="GB",IMAGE("https://logodownload.org/wp-content/uploads/2020/07/green-bay-packers-logo-1.png"),IF(BJ2="MIN",IMAGE("https://1000logos.net/wp-content/uploads/2017/06/Minnesota-Vikings-Logo-1965.png"),IF(BJ2="CHI",IMAGE("https://logos-world.net/wp-content/uploads/2020/05/Chicago-Bears-logo.png"),IF(BJ2="TB",IMAGE("https://logodownload.org/wp-content/uploads/2020/09/tampa-bay-buccaneers-logo.png"),IF(BJ2="NO",IMAGE("https://1000logos.net/wp-content/uploads/2017/04/New-Orleans-Saints-Logo.png"),IF(BJ2="ATL",IMAGE("https://logodownload.org/wp-content/uploads/2020/07/atlanta-falcons-logo-0.png"),IF(BJ2="CAR",IMAGE("https://logos-download.com/wp-content/uploads/2018/02/Carolina_Panthers_logo_blue.png"),"")))))))))))))))))))))))))))))))) | BL2: 17 | BM2: 24 | BN2: FALSE
