Workbook

Sheet Rules & Scoring
A1: INTRO
A2: We are back again with our third season! To everyone returning, welcome back. To the newcomers, glad to have you join us!
A3: Read the point system below carefully, and best of luck this season!
A4: PREDICTIONS AND WAGERS ARE DUE NO LATER THAN SEPTEMBER 7TH @ 5PM CENTRAL!
A5: APP UPDATES & NEW FEATURES
A6: • Quick Links: Easily navigate between weeks using the new Quick Links.
A7: • Live Standings Panel: You will now be able to see the Standings on the right side on Weeks tabs
A8: • Randomizer: The Randomizer located in H1 cell of Weeks tabs will now allow you multiple randomize options to fill out picks faster, or give yourself some new ideas!
A9: • Clearing in Bulk: You will also have multiple Clear options under the Randomizer dropdown.
A11: FILLING OUT PREDICTIONS (REGULAR SEASON)
A12: All you need to do for predictions is go through Weeks 1-18 and fill in:
A13: Winning Team
... A81: Rob Klezmer

Sheet Standings
B1: AFC West | C1: Record | D1: Div Record | G1: NFC West | H1: Record | I1: Div Record
A2: =IMAGE("https://logodownload.org/wp-content/uploads/2020/09/kansas-city-chiefs-logo.png") | B2: KC | C2: =CONCATENATE('Standings Counter'!B20," - ",'Standings Counter'!C20) -> 10 - 7 | D2: =CONCATENATE('Div Record Counter'!B20," - ",'Div Record Counter'!C20) -> 3 - 3 | F2: =IMAGE("https://logodownload.org/wp-content/uploads/2020/09/san-francisco-49ers-logo-2048x1220.png") | G2: SF | H2: =CONCATENATE('Standings Counter'!AH20," - ",'Standings Counter'!AI20) -> 10 - 7 | I2: =CONCATENATE('Div Record Counter'!AH20," - ",'Div Record Counter'!AI20) -> 4 - 2
A3: =IMAGE("https://logodownload.org/wp-content/uploads/2020/09/las-vegas-raiders-logo-1-564x599.png") | B3: LV | C3: =CONCATENATE('Standings Counter'!D20," - ",'Standings Counter'!E20) -> 7 - 10 | D3: =CONCATENATE('Div Record Counter'!D20," - ",'Div Record Counter'!E20) -> 2 - 4 | F3: =IMAGE("https://1000logos.net/wp-content/uploads/2018/07/Rams-Logo.png") | G3: LAR | H3: =CONCATENATE('Standings Counter'!AJ20," - ",'Standings Counter'!AK20) -> 13 - 4 | I3: =CONCATENATE('Div Record Counter'!AJ20," - ",'Div Record Counter'!AK20) -> 3 - 3
A4: =IMAGE("https://logodownload.org/wp-content/uploads/2020/07/denver-broncos-logo-0.png") | B4: DEN | C4: =CONCATENATE('Standings Counter'!F20," - ",'Standings Counter'!G20) -> 12 - 5 | D4: =CONCATENATE('Div Record Counter'!F20," - ",'Div Record Counter'!G20) -> 4 - 2 | F4: =IMAGE("https://cdn.freebiesupply.com/images/large/2x/seattle-seahawks-logo-transparent.png") | G4: SEA | H4: =CONCATENATE('Standings Counter'!AL20," - ",'Standings Counter'!AM20) -> 12 - 5 | I4: =CONCATENATE('Div Record Counter'!AL20," - ",'Div Record Counter'!AM20) -> 4 - 2
A5: =IMAGE("https://logosmarcas.net/wp-content/uploads/2020/07/Los-Angeles-Chargers-logo.png") | B5: LAC | C5: =CONCATENATE('Standings Counter'!H20," - ",'Standings Counter'!I20) -> 8 - 9 | D5: =concatenate('Div Record Counter'!H20," - ",'Div Record Counter'!I20) -> 3 - 3 | F5: =IMAGE("https://logos-world.net/wp-content/uploads/2020/05/Arizona-Cardinals-Logo.png") | G5: AZ | H5: =CONCATENATE('Standings Counter'!AN20," - ",'Standings Counter'!AO20) -> 5 - 12 | I5: =CONCATENATE('Div Record Counter'!AN20," - ",'Div Record Counter'!AO20) -> 1 - 5
B7: AFC East | C7: Record | D7: Div Record | G7: NFC East | H7: Record | I7: Div Record
A8: =IMAGE("https://logos-download.com/wp-content/uploads/2018/03/Buffalo_Bills_logo_blue.png") | B8: BUF | C8: =CONCATENATE('Standings Counter'!J20," - ",'Standings Counter'!K20) -> 12 - 5 | D8: =CONCATENATE('Div Record Counter'!J20," - ",'Div Record Counter'!K20) -> 3 - 3 | F8: =IMAGE("https://www.freepnglogos.com/uploads/dallas-cowboys-logo-22.png") | G8: DAL | H8: =CONCATENATE('Standings Counter'!AP20," - ",'Standings Counter'!AQ20) -> 11 - 6 | I8: =CONCATENATE('Div Record Counter'!AP20," - ",'Div Record Counter'!AQ20) -> 5 - 1
A9: =IMAGE("https://logos-world.net/wp-content/uploads/2020/05/Miami-Dolphins-Logo.png") | B9: MIA | C9: =CONCATENATE('Standings Counter'!L20," - ",'Standings Counter'!M20) -> 3 - 14 | D9: =concatenate('Div Record Counter'!L20," - ",'Div Record Counter'!M20) -> 1 - 5 | F9: =IMAGE("https://1000logos.net/wp-content/uploads/2017/05/Philadelphia-Eagles-Logo.png") | G9: PHI | H9: =CONCATENATE('Standings Counter'!AR20," - ",'Standings Counter'!AS20) -> 13 - 4 | I9: =CONCATENATE('Div Record Counter'!AR20," - ",'Div Record Counter'!AS20) -> 5 - 1
A10: =IMAGE("https://logos-world.net/wp-content/uploads/2020/07/New-York-Jets-Logo.png") | B10: NYJ | C10: =CONCATENATE('Standings Counter'!N20," - ",'Standings Counter'!O20) -> 4 - 13 | D10: =concatenate('Div Record Counter'!N20," - ",'Div Record Counter'!O20) -> 3 - 3 | F10: =IMAGE("https://logosmarcas.net/wp-content/uploads/2020/07/New-York-Giants-Logo.png") | G10: NYG | H10: =CONCATENATE('Standings Counter'!AT20," - ",'Standings Counter'!AU20) -> 4 - 13 | I10: =CONCATENATE('Div Record Counter'!AT20," - ",'Div Record Counter'!AU20) -> 0 - 6
A11: =IMAGE("https://purepng.com/public/uploads/large/new-england-patriots-logo-symbol-ucp.png") | B11: NE | C11: =CONCATENATE('Standings Counter'!P20," - ",'Standings Counter'!Q20) -> 13 - 4 | D11: =concatenate('Div Record Counter'!P20," - ",'Div Record Counter'!Q20) -> 5 - 1 | F11: =IMAGE("https://logodownload.org/wp-content/uploads/2020/09/washington-commanders-logo.png") | G11: WSH | H11: =CONCATENATE('Standings Counter'!AV20," - ",'Standings Counter'!AW20) -> 6 - 11 | I11: =CONCATENATE('Div Record Counter'!AV20," - ",'Div Record Counter'!AW20) -> 2 - 4
B13: AFC North | C13: Record | D13: Div Record | G13: NFC North | H13: Record | I13: Div Record
A14: =IMAGE("https://1000logos.net/wp-content/uploads/2016/10/Baltimore-Ravens-Logo.png") | B14: BAL | C14: =CONCATENATE('Standings Counter'!R20," - ",'Standings Counter'!S20) -> 11 - 6 | D14: =concatenate('Div Record Counter'!R20," - ",'Div Record Counter'!S20) -> 4 - 2 | F14: =IMAGE("https://logos-world.net/wp-content/uploads/2020/05/Detroit-Lions-Logo-2017-Present.png") | G14: DET | H14: =CONCATENATE('Standings Counter'!AX20," - ",'Standings Counter'!AY20) -> 11 - 6 | I14: =CONCATENATE('Div Record Counter'!AX20," - ",'Div Record Counter'!AY20) -> 3 - 3
A15: =IMAGE("https://logos-world.net/wp-content/uploads/2020/05/Cleveland-Browns-Logo-2006-2014.png") | B15: CLE | C15: =CONCATENATE('Standings Counter'!T20," - ",'Standings Counter'!U20) -> 4 - 13 | D15: =concatenate('Div Record Counter'!T20," - ",'Div Record Counter'!U20) -> 0 - 6 | F15: =IMAGE("https://logodownload.org/wp-content/uploads/2020/07/green-bay-packers-logo-1.png") | G15: GB | H15: =CONCATENATE('Standings Counter'!AZ20," - ",'Standings Counter'!BA20) -> 9 - 8 | I15: =CONCATENATE('Div Record Counter'!AZ20," - ",'Div Record Counter'!BA20) -> 3 - 3
A16: =IMAGE("https://1000logos.net/wp-content/uploads/2017/06/Pittsburgh-Steelers-Logo.png") | B16: PIT | C16: =CONCATENATE('Standings Counter'!V20," - ",'Standings Counter'!W20) -> 7 - 10 | D16: =concatenate('Div Record Counter'!V20," - ",'Div Record Counter'!W20) -> 3 - 3 | F16: =IMAGE("https://1000logos.net/wp-content/uploads/2017/06/Minnesota-Vikings-Logo-1965.png") | G16: MIN | H16: =CONCATENATE('Standings Counter'!BB20," - ",'Standings Counter'!BC20) -> 8 - 9 | I16: =CONCATENATE('Div Record Counter'!BB20," - ",'Div Record Counter'!BC20) -> 1 - 5
A17: =IMAGE("https://logos-world.net/wp-content/uploads/2020/05/Cincinnati-Bengals-Logo.png") | B17: CIN | C17: =CONCATENATE('Standings Counter'!X20," - ",'Standings Counter'!Y20) -> 10 - 7 | D17: =concatenate('Div Record Counter'!X20," - ",'Div Record Counter'!Y20) -> 5 - 1 | F17: =IMAGE("https://logos-world.net/wp-content/uploads/2020/05/Chicago-Bears-logo.png") | G17: CHI | H17: =CONCATENATE('Standings Counter'!BD20," - ",'Standings Counter'!BE20) -> 10 - 7 | I17: =CONCATENATE('Div Record Counter'!BD20," - ",'Div Record Counter'!BE20) -> 5 - 1
B19: AFC South | C19: Record | D19: Div Record | G19: NFC South | H19: Record | I19: Div Record
A20: =IMAGE("https://cdn.wallpapersafari.com/15/25/Jnl2Yc.png") | B20: HOU | C20: =CONCATENATE('Standings Counter'!Z20," - ",'Standings Counter'!AA20) -> 10 - 7 | D20: =concatenate('Div Record Counter'!Z20," - ",'Div Record Counter'!AA20) -> 5 - 1 | F20: =IMAGE("https://logodownload.org/wp-content/uploads/2020/09/tampa-bay-buccaneers-logo.png") | G20: TB | H20: =CONCATENATE('Standings Counter'!BF20," - ",'Standings Counter'!BG20) -> 8 - 9 | I20: =CONCATENATE('Div Record Counter'!BF20," - ",'Div Record Counter'!BG20) -> 3 - 3
A21: =IMAGE("https://1000logos.net/wp-content/uploads/2018/07/Jacksonville-Jaguars-Logo-1536x960.png") | B21: JAX | C21: =CONCATENATE('Standings Counter'!AB20," - ",'Standings Counter'!AC20) -> 10 - 7 | D21: =concatenate('Div Record Counter'!AB20," - ",'Div Record Counter'!AC20) -> 5 - 1 | F21: =IMAGE("https://1000logos.net/wp-content/uploads/2017/04/New-Orleans-Saints-Logo.png") | G21: NO | H21: =CONCATENATE('Standings Counter'!BH20," - ",'Standings Counter'!BI20) -> 9 - 8 | I21: =CONCATENATE('Div Record Counter'!BH20," - ",'Div Record Counter'!BI20) -> 4 - 2
A22: =IMAGE("https://1000logos.net/wp-content/uploads/2016/12/Indianapolis-Colts-Logo-2048x1280.png") | B22: IND | C22: =CONCATENATE('Standings Counter'!AD20," - ",'Standings Counter'!AE20) -> 7 - 10 | D22: =concatenate('Div Record Counter'!AD20," - ",'Div Record Counter'!AE20) -> 2 - 4 | F22: =IMAGE("https://logodownload.org/wp-content/uploads/2020/07/atlanta-falcons-logo-0.png") | G22: ATL | H22: =CONCATENATE('Standings Counter'!BJ20," - ",'Standings Counter'!BK20) -> 8 - 9 | I22: =CONCATENATE('Div Record Counter'!BJ20," - ",'Div Record Counter'!BK20) -> 4 - 2
A23: =IMAGE("https://img-s-msn-com.akamaized.net/tenant/amp/entityid/AA1YwbtK.img?w=720&h=720&m=6") | B23: TEN | C23: =CONCATENATE('Standings Counter'!AF20," - ",'Standings Counter'!AG20) -> 3 - 14 | D23: =concatenate('Div Record Counter'!AF20," - ",'Div Record Counter'!AG20) -> 0 - 6 | F23: =IMAGE("https://logos-download.com/wp-content/uploads/2018/02/Carolina_Panthers_logo_blue.png") | G23: CAR | H23: =CONCATENATE('Standings Counter'!BL20," - ",'Standings Counter'!BM20) -> 4 - 13 | I23: =CONCATENATE('Div Record Counter'!BL20," - ",'Div Record Counter'!BM20) -> 1 - 5
B25: AFC Playoff Picture | G25: NFC Playoff Picture
A26: 1 | B26: {=INDEX('Playoffs Calc'!T5,0)} -> NE | C26: =IF(B26="KC",IMAGE("https://logodownload.org/wp-content/uploads/2020/09/kansas-city-chiefs-logo.png"),IF(B26="LV",IMAGE("https://logodownload.org/wp-content/uploads/2020/09/las-vegas-raiders-logo-1-564x599.png"),IF(B26="DEN",IMAGE("https://logodownload.org/wp-content/uploads/2020/07/denver-broncos-logo-0.png"),IF(B26="LAC",IMAGE("https://logosmarcas.net/wp-content/uploads/2020/07/Los-Angeles-Chargers-logo.png"),IF(B26="BUF",IMAGE("https://logos-download.com/wp-content/uploads/2018/03/Buffalo_Bills_logo_blue.png"),IF(B26="MIA",IMAGE("https://logos-world.net/wp-content/uploads/2020/05/Miami-Dolphins-Logo.png"),IF(B26="NYJ",IMAGE("https://logos-world.net/wp-content/uploads/2020/07/New-York-Jets-Logo.png"),IF(B26="NE",IMAGE("https://purepng.com/public/uploads/large/new-england-patriots-logo-symbol-ucp.png"),IF(B26="BAL",IMAGE("https://1000logos.net/wp-content/uploads/2016/10/Baltimore-Ravens-Logo.png"),IF(B26="CLE",IMAGE("https://logos-world.net/wp-content/uploads/2020/05/Cleveland-Browns-Logo-2006-2014.png"),IF(B26="PIT",IMAGE("https://1000logos.net/wp-content/uploads/2017/06/Pittsburgh-Steelers-Logo.png"),IF(B26="CIN",IMAGE("https://logos-world.net/wp-content/uploads/2020/05/Cincinnati-Bengals-Logo.png"),IF(B26="HOU",IMAGE("https://cdn.wallpapersafari.com/15/25/Jnl2Yc.png"),IF(B26="JAX",IMAGE("https://1000logos.net/wp-content/uploads/2018/07/Jacksonville-Jaguars-Logo-1536x960.png"),IF(B26="IND",IMAGE("https://1000logos.net/wp-content/uploads/2016/12/Indianapolis-Colts-Logo-2048x1280.png"),IF(B26="TEN",IMAGE("https://img-s-msn-com.akamaized.net/tenant/amp/entityid/AA1YwbtK.img?w=720&h=720&m=6"),IF(B26="SF",IMAGE("https://logodownload.org/wp-content/uploads/2020/09/san-francisco-49ers-logo-2048x1220.png"),IF(B26="LAR",IMAGE("https://1000logos.net/wp-content/uploads/2018/07/Rams-Logo.png"),IF(B26="SEA",IMAGE("https://cdn.freebiesupply.com/images/large/2x/seattle-seahawks-logo-transparent.png"),IF(B26="AZ",IMAGE("https://logos-world.net/wp-content/uploads/2020/05/Arizona-Cardinals-Logo.png"),IF(B26="DAL",IMAGE("https://www.freepnglogos.com/uploads/dallas-cowboys-logo-22.png"),IF(B26="PHI",IMAGE("https://1000logos.net/wp-content/uploads/2017/05/Philadelphia-Eagles-Logo.png"),IF(B26="NYG",IMAGE("https://logosmarcas.net/wp-content/uploads/2020/07/New-York-Giants-Logo.png"),IF(B26="WSH",IMAGE("https://logodownload.org/wp-content/uploads/2020/09/washington-commanders-logo.png"),IF(B26="DET",IMAGE("https://logos-world.net/wp-content/uploads/2020/05/Detroit-Lions-Logo-2017-Present.png"),IF(B26="GB",IMAGE("https://logodownload.org/wp-content/uploads/2020/07/green-bay-packers-logo-1.png"),IF(B26="MIN",IMAGE("https://1000logos.net/wp-content/uploads/2017/06/Minnesota-Vikings-Logo-1965.png"),IF(B26="CHI",IMAGE("https://logos-world.net/wp-content/uploads/2020/05/Chicago-Bears-logo.png"),IF(B26="TB",IMAGE("https://logodownload.org/wp-content/uploads/2020/09/tampa-bay-buccaneers-logo.png"),IF(B26="NO",IMAGE("https://1000logos.net/wp-content/uploads/2017/04/New-Orleans-Saints-Logo.png"),IF(B26="ATL",IMAGE("https://logodownload.org/wp-content/uploads/2020/07/atlanta-falcons-logo-0.png"),IF(B26="CAR",IMAGE("https://logos-download.com/wp-content/uploads/2018/02/Carolina_Panthers_logo_blue.png"),"")))))))))))))))))))))))))))))))) | F26: 1 | G26: {=INDEX('Playoffs Calc'!T18,0)} -> PHI | H26: =IF(G26="KC",IMAGE("https://logodownload.org/wp-content/uploads/2020/09/kansas-city-chiefs-logo.png"),IF(G26="LV",IMAGE("https://logodownload.org/wp-content/uploads/2020/09/las-vegas-raiders-logo-1-564x599.png"),IF(G26="DEN",IMAGE("https://logodownload.org/wp-content/uploads/2020/07/denver-broncos-logo-0.png"),IF(G26="LAC",IMAGE("https://logosmarcas.net/wp-content/uploads/2020/07/Los-Angeles-Chargers-logo.png"),IF(G26="BUF",IMAGE("https://logos-download.com/wp-content/uploads/2018/03/Buffalo_Bills_logo_blue.png"),IF(G26="MIA",IMAGE("https://logos-world.net/wp-content/uploads/2020/05/Miami-Dolphins-Logo.png"),IF(G26="NYJ",IMAGE("https://logos-world.net/wp-content/uploads/2020/07/New-York-Jets-Logo.png"),IF(G26="NE",IMAGE("https://purepng.com/public/uploads/large/new-england-patriots-logo-symbol-ucp.png"),IF(G26="BAL",IMAGE("https://1000logos.net/wp-content/uploads/2016/10/Baltimore-Ravens-Logo.png"),IF(G26="CLE",IMAGE("https://logos-world.net/wp-content/uploads/2020/05/Cleveland-Browns-Logo-2006-2014.png"),IF(G26="PIT",IMAGE("https://1000logos.net/wp-content/uploads/2017/06/Pittsburgh-Steelers-Logo.png"),IF(G26="CIN",IMAGE("https://logos-world.net/wp-content/uploads/2020/05/Cincinnati-Bengals-Logo.png"),IF(G26="HOU",IMAGE("https://cdn.wallpapersafari.com/15/25/Jnl2Yc.png"),IF(G26="JAX",IMAGE("https://1000logos.net/wp-content/uploads/2018/07/Jacksonville-Jaguars-Logo-1536x960.png"),IF(G26="IND",IMAGE("https://1000logos.net/wp-content/uploads/2016/12/Indianapolis-Colts-Logo-2048x1280.png"),IF(G26="TEN",IMAGE("https://img-s-msn-com.akamaized.net/tenant/amp/entityid/AA1YwbtK.img?w=720&h=720&m=6"),IF(G26="SF",IMAGE("https://logodownload.org/wp-content/uploads/2020/09/san-francisco-49ers-logo-2048x1220.png"),IF(G26="LAR",IMAGE("https://1000logos.net/wp-content/uploads/2018/07/Rams-Logo.png"),IF(G26="SEA",IMAGE("https://cdn.freebiesupply.com/images/large/2x/seattle-seahawks-logo-transparent.png"),IF(G26="AZ",IMAGE("https://logos-world.net/wp-content/uploads/2020/05/Arizona-Cardinals-Logo.png"),IF(G26="DAL",IMAGE("https://www.freepnglogos.com/uploads/dallas-cowboys-logo-22.png"),IF(G26="PHI",IMAGE("https://1000logos.net/wp-content/uploads/2017/05/Philadelphia-Eagles-Logo.png"),IF(G26="NYG",IMAGE("https://logosmarcas.net/wp-content/uploads/2020/07/New-York-Giants-Logo.png"),IF(G26="WSH",IMAGE("https://logodownload.org/wp-content/uploads/2020/09/washington-commanders-logo.png"),IF(G26="DET",IMAGE("https://logos-world.net/wp-content/uploads/2020/05/Detroit-Lions-Logo-2017-Present.png"),IF(G26="GB",IMAGE("https://logodownload.org/wp-content/uploads/2020/07/green-bay-packers-logo-1.png"),IF(G26="MIN",IMAGE("https://1000logos.net/wp-content/uploads/2017/06/Minnesota-Vikings-Logo-1965.png"),IF(G26="CHI",IMAGE("https://logos-world.net/wp-content/uploads/2020/05/Chicago-Bears-logo.png"),IF(G26="TB",IMAGE("https://logodownload.org/wp-content/uploads/2020/09/tampa-bay-buccaneers-logo.png"),IF(G26="NO",IMAGE("https://1000logos.net/wp-content/uploads/2017/04/New-Orleans-Saints-Logo.png"),IF(G26="ATL",IMAGE("https://logodownload.org/wp-content/uploads/2020/07/atlanta-falcons-logo-0.png"),IF(G26="CAR",IMAGE("https://logos-download.com/wp-content/uploads/2018/02/Carolina_Panthers_logo_blue.png"),""))))))))))))))))))))))))))))))))
A27: 2 | B27: {=INDEX('Playoffs Calc'!T6,0)} -> DEN | C27: =IF(B27="KC",IMAGE("https://logodownload.org/wp-content/uploads/2020/09/kansas-city-chiefs-logo.png"),IF(B27="LV",IMAGE("https://logodownload.org/wp-content/uploads/2020/09/las-vegas-raiders-logo-1-564x599.png"),IF(B27="DEN",IMAGE("https://logodownload.org/wp-content/uploads/2020/07/denver-broncos-logo-0.png"),IF(B27="LAC",IMAGE("https://logosmarcas.net/wp-content/uploads/2020/07/Los-Angeles-Chargers-logo.png"),IF(B27="BUF",IMAGE("https://logos-download.com/wp-content/uploads/2018/03/Buffalo_Bills_logo_blue.png"),IF(B27="MIA",IMAGE("https://logos-world.net/wp-content/uploads/2020/05/Miami-Dolphins-Logo.png"),IF(B27="NYJ",IMAGE("https://logos-world.net/wp-content/uploads/2020/07/New-York-Jets-Logo.png"),IF(B27="NE",IMAGE("https://purepng.com/public/uploads/large/new-england-patriots-logo-symbol-ucp.png"),IF(B27="BAL",IMAGE("https://1000logos.net/wp-content/uploads/2016/10/Baltimore-Ravens-Logo.png"),IF(B27="CLE",IMAGE("https://logos-world.net/wp-content/uploads/2020/05/Cleveland-Browns-Logo-2006-2014.png"),IF(B27="PIT",IMAGE("https://1000logos.net/wp-content/uploads/2017/06/Pittsburgh-Steelers-Logo.png"),IF(B27="CIN",IMAGE("https://logos-world.net/wp-content/uploads/2020/05/Cincinnati-Bengals-Logo.png"),IF(B27="HOU",IMAGE("https://cdn.wallpapersafari.com/15/25/Jnl2Yc.png"),IF(B27="JAX",IMAGE("https://1000logos.net/wp-content/uploads/2018/07/Jacksonville-Jaguars-Logo-1536x960.png"),IF(B27="IND",IMAGE("https://1000logos.net/wp-content/uploads/2016/12/Indianapolis-Colts-Logo-2048x1280.png"),IF(B27="TEN",IMAGE("https://img-s-msn-com.akamaized.net/tenant/amp/entityid/AA1YwbtK.img?w=720&h=720&m=6"),IF(B27="SF",IMAGE("https://logodownload.org/wp-content/uploads/2020/09/san-francisco-49ers-logo-2048x1220.png"),IF(B27="LAR",IMAGE("https://1000logos.net/wp-content/uploads/2018/07/Rams-Logo.png"),IF(B27="SEA",IMAGE("https://cdn.freebiesupply.com/images/large/2x/seattle-seahawks-logo-transparent.png"),IF(B27="AZ",IMAGE("https://logos-world.net/wp-content/uploads/2020/05/Arizona-Cardinals-Logo.png"),IF(B27="DAL",IMAGE("https://www.freepnglogos.com/uploads/dallas-cowboys-logo-22.png"),IF(B27="PHI",IMAGE("https://1000logos.net/wp-content/uploads/2017/05/Philadelphia-Eagles-Logo.png"),IF(B27="NYG",IMAGE("https://logosmarcas.net/wp-content/uploads/2020/07/New-York-Giants-Logo.png"),IF(B27="WSH",IMAGE("https://logodownload.org/wp-content/uploads/2020/09/washington-commanders-logo.png"),IF(B27="DET",IMAGE("https://logos-world.net/wp-content/uploads/2020/05/Detroit-Lions-Logo-2017-Present.png"),IF(B27="GB",IMAGE("https://logodownload.org/wp-content/uploads/2020/07/green-bay-packers-logo-1.png"),IF(B27="MIN",IMAGE("https://1000logos.net/wp-content/uploads/2017/06/Minnesota-Vikings-Logo-1965.png"),IF(B27="CHI",IMAGE("https://logos-world.net/wp-content/uploads/2020/05/Chicago-Bears-logo.png"),IF(B27="TB",IMAGE("https://logodownload.org/wp-content/uploads/2020/09/tampa-bay-buccaneers-logo.png"),IF(B27="NO",IMAGE("https://1000logos.net/wp-content/uploads/2017/04/New-Orleans-Saints-Logo.png"),IF(B27="ATL",IMAGE("https://logodownload.org/wp-content/uploads/2020/07/atlanta-falcons-logo-0.png"),IF(B27="CAR",IMAGE("https://logos-download.com/wp-content/uploads/2018/02/Carolina_Panthers_logo_blue.png"),"")))))))))))))))))))))))))))))))) | F27: 2 | G27: {=INDEX('Playoffs Calc'!T19,0)} -> LAR | H27: =IF(G27="KC",IMAGE("https://logodownload.org/wp-content/uploads/2020/09/kansas-city-chiefs-logo.png"),IF(G27="LV",IMAGE("https://logodownload.org/wp-content/uploads/2020/09/las-vegas-raiders-logo-1-564x599.png"),IF(G27="DEN",IMAGE("https://logodownload.org/wp-content/uploads/2020/07/denver-broncos-logo-0.png"),IF(G27="LAC",IMAGE("https://logosmarcas.net/wp-content/uploads/2020/07/Los-Angeles-Chargers-logo.png"),IF(G27="BUF",IMAGE("https://logos-download.com/wp-content/uploads/2018/03/Buffalo_Bills_logo_blue.png"),IF(G27="MIA",IMAGE("https://logos-world.net/wp-content/uploads/2020/05/Miami-Dolphins-Logo.png"),IF(G27="NYJ",IMAGE("https://logos-world.net/wp-content/uploads/2020/07/New-York-Jets-Logo.png"),IF(G27="NE",IMAGE("https://purepng.com/public/uploads/large/new-england-patriots-logo-symbol-ucp.png"),IF(G27="BAL",IMAGE("https://1000logos.net/wp-content/uploads/2016/10/Baltimore-Ravens-Logo.png"),IF(G27="CLE",IMAGE("https://logos-world.net/wp-content/uploads/2020/05/Cleveland-Browns-Logo-2006-2014.png"),IF(G27="PIT",IMAGE("https://1000logos.net/wp-content/uploads/2017/06/Pittsburgh-Steelers-Logo.png"),IF(G27="CIN",IMAGE("https://logos-world.net/wp-content/uploads/2020/05/Cincinnati-Bengals-Logo.png"),IF(G27="HOU",IMAGE("https://cdn.wallpapersafari.com/15/25/Jnl2Yc.png"),IF(G27="JAX",IMAGE("https://1000logos.net/wp-content/uploads/2018/07/Jacksonville-Jaguars-Logo-1536x960.png"),IF(G27="IND",IMAGE("https://1000logos.net/wp-content/uploads/2016/12/Indianapolis-Colts-Logo-2048x1280.png"),IF(G27="TEN",IMAGE("https://img-s-msn-com.akamaized.net/tenant/amp/entityid/AA1YwbtK.img?w=720&h=720&m=6"),IF(G27="SF",IMAGE("https://logodownload.org/wp-content/uploads/2020/09/san-francisco-49ers-logo-2048x1220.png"),IF(G27="LAR",IMAGE("https://1000logos.net/wp-content/uploads/2018/07/Rams-Logo.png"),IF(G27="SEA",IMAGE("https://cdn.freebiesupply.com/images/large/2x/seattle-seahawks-logo-transparent.png"),IF(G27="AZ",IMAGE("https://logos-world.net/wp-content/uploads/2020/05/Arizona-Cardinals-Logo.png"),IF(G27="DAL",IMAGE("https://www.freepnglogos.com/uploads/dallas-cowboys-logo-22.png"),IF(G27="PHI",IMAGE("https://1000logos.net/wp-content/uploads/2017/05/Philadelphia-Eagles-Logo.png"),IF(G27="NYG",IMAGE("https://logosmarcas.net/wp-content/uploads/2020/07/New-York-Giants-Logo.png"),IF(G27="WSH",IMAGE("https://logodownload.org/wp-content/uploads/2020/09/washington-commanders-logo.png"),IF(G27="DET",IMAGE("https://logos-world.net/wp-content/uploads/2020/05/Detroit-Lions-Logo-2017-Present.png"),IF(G27="GB",IMAGE("https://logodownload.org/wp-content/uploads/2020/07/green-bay-packers-logo-1.png"),IF(G27="MIN",IMAGE("https://1000logos.net/wp-content/uploads/2017/06/Minnesota-Vikings-Logo-1965.png"),IF(G27="CHI",IMAGE("https://logos-world.net/wp-content/uploads/2020/05/Chicago-Bears-logo.png"),IF(G27="TB",IMAGE("https://logodownload.org/wp-content/uploads/2020/09/tampa-bay-buccaneers-logo.png"),IF(G27="NO",IMAGE("https://1000logos.net/wp-content/uploads/2017/04/New-Orleans-Saints-Logo.png"),IF(G27="ATL",IMAGE("https://logodownload.org/wp-content/uploads/2020/07/atlanta-falcons-logo-0.png"),IF(G27="CAR",IMAGE("https://logos-download.com/wp-content/uploads/2018/02/Carolina_Panthers_logo_blue.png"),""))))))))))))))))))))))))))))))))
A28: 3 | B28: {=INDEX('Playoffs Calc'!T7,0)} -> BAL | C28: =IF(B28="KC",IMAGE("https://logodownload.org/wp-content/uploads/2020/09/kansas-city-chiefs-logo.png"),IF(B28="LV",IMAGE("https://logodownload.org/wp-content/uploads/2020/09/las-vegas-raiders-logo-1-564x599.png"),IF(B28="DEN",IMAGE("https://logodownload.org/wp-content/uploads/2020/07/denver-broncos-logo-0.png"),IF(B28="LAC",IMAGE("https://logosmarcas.net/wp-content/uploads/2020/07/Los-Angeles-Chargers-logo.png"),IF(B28="BUF",IMAGE("https://logos-download.com/wp-content/uploads/2018/03/Buffalo_Bills_logo_blue.png"),IF(B28="MIA",IMAGE("https://logos-world.net/wp-content/uploads/2020/05/Miami-Dolphins-Logo.png"),IF(B28="NYJ",IMAGE("https://logos-world.net/wp-content/uploads/2020/07/New-York-Jets-Logo.png"),IF(B28="NE",IMAGE("https://purepng.com/public/uploads/large/new-england-patriots-logo-symbol-ucp.png"),IF(B28="BAL",IMAGE("https://1000logos.net/wp-content/uploads/2016/10/Baltimore-Ravens-Logo.png"),IF(B28="CLE",IMAGE("https://logos-world.net/wp-content/uploads/2020/05/Cleveland-Browns-Logo-2006-2014.png"),IF(B28="PIT",IMAGE("https://1000logos.net/wp-content/uploads/2017/06/Pittsburgh-Steelers-Logo.png"),IF(B28="CIN",IMAGE("https://logos-world.net/wp-content/uploads/2020/05/Cincinnati-Bengals-Logo.png"),IF(B28="HOU",IMAGE("https://cdn.wallpapersafari.com/15/25/Jnl2Yc.png"),IF(B28="JAX",IMAGE("https://1000logos.net/wp-content/uploads/2018/07/Jacksonville-Jaguars-Logo-1536x960.png"),IF(B28="IND",IMAGE("https://1000logos.net/wp-content/uploads/2016/12/Indianapolis-Colts-Logo-2048x1280.png"),IF(B28="TEN",IMAGE("https://img-s-msn-com.akamaized.net/tenant/amp/entityid/AA1YwbtK.img?w=720&h=720&m=6"),IF(B28="SF",IMAGE("https://logodownload.org/wp-content/uploads/2020/09/san-francisco-49ers-logo-2048x1220.png"),IF(B28="LAR",IMAGE("https://1000logos.net/wp-content/uploads/2018/07/Rams-Logo.png"),IF(B28="SEA",IMAGE("https://cdn.freebiesupply.com/images/large/2x/seattle-seahawks-logo-transparent.png"),IF(B28="AZ",IMAGE("https://logos-world.net/wp-content/uploads/2020/05/Arizona-Cardinals-Logo.png"),IF(B28="DAL",IMAGE("https://www.freepnglogos.com/uploads/dallas-cowboys-logo-22.png"),IF(B28="PHI",IMAGE("https://1000logos.net/wp-content/uploads/2017/05/Philadelphia-Eagles-Logo.png"),IF(B28="NYG",IMAGE("https://logosmarcas.net/wp-content/uploads/2020/07/New-York-Giants-Logo.png"),IF(B28="WSH",IMAGE("https://logodownload.org/wp-content/uploads/2020/09/washington-commanders-logo.png"),IF(B28="DET",IMAGE("https://logos-world.net/wp-content/uploads/2020/05/Detroit-Lions-Logo-2017-Present.png"),IF(B28="GB",IMAGE("https://logodownload.org/wp-content/uploads/2020/07/green-bay-packers-logo-1.png"),IF(B28="MIN",IMAGE("https://1000logos.net/wp-content/uploads/2017/06/Minnesota-Vikings-Logo-1965.png"),IF(B28="CHI",IMAGE("https://logos-world.net/wp-content/uploads/2020/05/Chicago-Bears-logo.png"),IF(B28="TB",IMAGE("https://logodownload.org/wp-content/uploads/2020/09/tampa-bay-buccaneers-logo.png"),IF(B28="NO",IMAGE("https://1000logos.net/wp-content/uploads/2017/04/New-Orleans-Saints-Logo.png"),IF(B28="ATL",IMAGE("https://logodownload.org/wp-content/uploads/2020/07/atlanta-falcons-logo-0.png"),IF(B28="CAR",IMAGE("https://logos-download.com/wp-content/uploads/2018/02/Carolina_Panthers_logo_blue.png"),"")))))))))))))))))))))))))))))))) | F28: 3 | G28: {=INDEX('Playoffs Calc'!T20,0)} -> DET | H28: =IF(G28="KC",IMAGE("https://logodownload.org/wp-content/uploads/2020/09/kansas-city-chiefs-logo.png"),IF(G28="LV",IMAGE("https://logodownload.org/wp-content/uploads/2020/09/las-vegas-raiders-logo-1-564x599.png"),IF(G28="DEN",IMAGE("https://logodownload.org/wp-content/uploads/2020/07/denver-broncos-logo-0.png"),IF(G28="LAC",IMAGE("https://logosmarcas.net/wp-content/uploads/2020/07/Los-Angeles-Chargers-logo.png"),IF(G28="BUF",IMAGE("https://logos-download.com/wp-content/uploads/2018/03/Buffalo_Bills_logo_blue.png"),IF(G28="MIA",IMAGE("https://logos-world.net/wp-content/uploads/2020/05/Miami-Dolphins-Logo.png"),IF(G28="NYJ",IMAGE("https://logos-world.net/wp-content/uploads/2020/07/New-York-Jets-Logo.png"),IF(G28="NE",IMAGE("https://purepng.com/public/uploads/large/new-england-patriots-logo-symbol-ucp.png"),IF(G28="BAL",IMAGE("https://1000logos.net/wp-content/uploads/2016/10/Baltimore-Ravens-Logo.png"),IF(G28="CLE",IMAGE("https://logos-world.net/wp-content/uploads/2020/05/Cleveland-Browns-Logo-2006-2014.png"),IF(G28="PIT",IMAGE("https://1000logos.net/wp-content/uploads/2017/06/Pittsburgh-Steelers-Logo.png"),IF(G28="CIN",IMAGE("https://logos-world.net/wp-content/uploads/2020/05/Cincinnati-Bengals-Logo.png"),IF(G28="HOU",IMAGE("https://cdn.wallpapersafari.com/15/25/Jnl2Yc.png"),IF(G28="JAX",IMAGE("https://1000logos.net/wp-content/uploads/2018/07/Jacksonville-Jaguars-Logo-1536x960.png"),IF(G28="IND",IMAGE("https://1000logos.net/wp-content/uploads/2016/12/Indianapolis-Colts-Logo-2048x1280.png"),IF(G28="TEN",IMAGE("https://img-s-msn-com.akamaized.net/tenant/amp/entityid/AA1YwbtK.img?w=720&h=720&m=6"),IF(G28="SF",IMAGE("https://logodownload.org/wp-content/uploads/2020/09/san-francisco-49ers-logo-2048x1220.png"),IF(G28="LAR",IMAGE("https://1000logos.net/wp-content/uploads/2018/07/Rams-Logo.png"),IF(G28="SEA",IMAGE("https://cdn.freebiesupply.com/images/large/2x/seattle-seahawks-logo-transparent.png"),IF(G28="AZ",IMAGE("https://logos-world.net/wp-content/uploads/2020/05/Arizona-Cardinals-Logo.png"),IF(G28="DAL",IMAGE("https://www.freepnglogos.com/uploads/dallas-cowboys-logo-22.png"),IF(G28="PHI",IMAGE("https://1000logos.net/wp-content/uploads/2017/05/Philadelphia-Eagles-Logo.png"),IF(G28="NYG",IMAGE("https://logosmarcas.net/wp-content/uploads/2020/07/New-York-Giants-Logo.png"),IF(G28="WSH",IMAGE("https://logodownload.org/wp-content/uploads/2020/09/washington-commanders-logo.png"),IF(G28="DET",IMAGE("https://logos-world.net/wp-content/uploads/2020/05/Detroit-Lions-Logo-2017-Present.png"),IF(G28="GB",IMAGE("https://logodownload.org/wp-content/uploads/2020/07/green-bay-packers-logo-1.png"),IF(G28="MIN",IMAGE("https://1000logos.net/wp-content/uploads/2017/06/Minnesota-Vikings-Logo-1965.png"),IF(G28="CHI",IMAGE("https://logos-world.net/wp-content/uploads/2020/05/Chicago-Bears-logo.png"),IF(G28="TB",IMAGE("https://logodownload.org/wp-content/uploads/2020/09/tampa-bay-buccaneers-logo.png"),IF(G28="NO",IMAGE("https://1000logos.net/wp-content/uploads/2017/04/New-Orleans-Saints-Logo.png"),IF(G28="ATL",IMAGE("https://logodownload.org/wp-content/uploads/2020/07/atlanta-falcons-logo-0.png"),IF(G28="CAR",IMAGE("https://logos-download.com/wp-content/uploads/2018/02/Carolina_Panthers_logo_blue.png"),""))))))))))))))))))))))))))))))))
A29: 4 | B29: {=INDEX('Playoffs Calc'!T8,0)} -> HOU | C29: =IF(B29="KC",IMAGE("https://logodownload.org/wp-content/uploads/2020/09/kansas-city-chiefs-logo.png"),IF(B29="LV",IMAGE("https://logodownload.org/wp-content/uploads/2020/09/las-vegas-raiders-logo-1-564x599.png"),IF(B29="DEN",IMAGE("https://logodownload.org/wp-content/uploads/2020/07/denver-broncos-logo-0.png"),IF(B29="LAC",IMAGE("https://logosmarcas.net/wp-content/uploads/2020/07/Los-Angeles-Chargers-logo.png"),IF(B29="BUF",IMAGE("https://logos-download.com/wp-content/uploads/2018/03/Buffalo_Bills_logo_blue.png"),IF(B29="MIA",IMAGE("https://logos-world.net/wp-content/uploads/2020/05/Miami-Dolphins-Logo.png"),IF(B29="NYJ",IMAGE("https://logos-world.net/wp-content/uploads/2020/07/New-York-Jets-Logo.png"),IF(B29="NE",IMAGE("https://purepng.com/public/uploads/large/new-england-patriots-logo-symbol-ucp.png"),IF(B29="BAL",IMAGE("https://1000logos.net/wp-content/uploads/2016/10/Baltimore-Ravens-Logo.png"),IF(B29="CLE",IMAGE("https://logos-world.net/wp-content/uploads/2020/05/Cleveland-Browns-Logo-2006-2014.png"),IF(B29="PIT",IMAGE("https://1000logos.net/wp-content/uploads/2017/06/Pittsburgh-Steelers-Logo.png"),IF(B29="CIN",IMAGE("https://logos-world.net/wp-content/uploads/2020/05/Cincinnati-Bengals-Logo.png"),IF(B29="HOU",IMAGE("https://cdn.wallpapersafari.com/15/25/Jnl2Yc.png"),IF(B29="JAX",IMAGE("https://1000logos.net/wp-content/uploads/2018/07/Jacksonville-Jaguars-Logo-1536x960.png"),IF(B29="IND",IMAGE("https://1000logos.net/wp-content/uploads/2016/12/Indianapolis-Colts-Logo-2048x1280.png"),IF(B29="TEN",IMAGE("https://img-s-msn-com.akamaized.net/tenant/amp/entityid/AA1YwbtK.img?w=720&h=720&m=6"),IF(B29="SF",IMAGE("https://logodownload.org/wp-content/uploads/2020/09/san-francisco-49ers-logo-2048x1220.png"),IF(B29="LAR",IMAGE("https://1000logos.net/wp-content/uploads/2018/07/Rams-Logo.png"),IF(B29="SEA",IMAGE("https://cdn.freebiesupply.com/images/large/2x/seattle-seahawks-logo-transparent.png"),IF(B29="AZ",IMAGE("https://logos-world.net/wp-content/uploads/2020/05/Arizona-Cardinals-Logo.png"),IF(B29="DAL",IMAGE("https://www.freepnglogos.com/uploads/dallas-cowboys-logo-22.png"),IF(B29="PHI",IMAGE("https://1000logos.net/wp-content/uploads/2017/05/Philadelphia-Eagles-Logo.png"),IF(B29="NYG",IMAGE("https://logosmarcas.net/wp-content/uploads/2020/07/New-York-Giants-Logo.png"),IF(B29="WSH",IMAGE("https://logodownload.org/wp-content/uploads/2020/09/washington-commanders-logo.png"),IF(B29="DET",IMAGE("https://logos-world.net/wp-content/uploads/2020/05/Detroit-Lions-Logo-2017-Present.png"),IF(B29="GB",IMAGE("https://logodownload.org/wp-content/uploads/2020/07/green-bay-packers-logo-1.png"),IF(B29="MIN",IMAGE("https://1000logos.net/wp-content/uploads/2017/06/Minnesota-Vikings-Logo-1965.png"),IF(B29="CHI",IMAGE("https://logos-world.net/wp-content/uploads/2020/05/Chicago-Bears-logo.png"),IF(B29="TB",IMAGE("https://logodownload.org/wp-content/uploads/2020/09/tampa-bay-buccaneers-logo.png"),IF(B29="NO",IMAGE("https://1000logos.net/wp-content/uploads/2017/04/New-Orleans-Saints-Logo.png"),IF(B29="ATL",IMAGE("https://logodownload.org/wp-content/uploads/2020/07/atlanta-falcons-logo-0.png"),IF(B29="CAR",IMAGE("https://logos-download.com/wp-content/uploads/2018/02/Carolina_Panthers_logo_blue.png"),"")))))))))))))))))))))))))))))))) | F29: 4 | G29: {=INDEX('Playoffs Calc'!T21,0)} -> NO | H29: =IF(G29="KC",IMAGE("https://logodownload.org/wp-content/uploads/2020/09/kansas-city-chiefs-logo.png"),IF(G29="LV",IMAGE("https://logodownload.org/wp-content/uploads/2020/09/las-vegas-raiders-logo-1-564x599.png"),IF(G29="DEN",IMAGE("https://logodownload.org/wp-content/uploads/2020/07/denver-broncos-logo-0.png"),IF(G29="LAC",IMAGE("https://logosmarcas.net/wp-content/uploads/2020/07/Los-Angeles-Chargers-logo.png"),IF(G29="BUF",IMAGE("https://logos-download.com/wp-content/uploads/2018/03/Buffalo_Bills_logo_blue.png"),IF(G29="MIA",IMAGE("https://logos-world.net/wp-content/uploads/2020/05/Miami-Dolphins-Logo.png"),IF(G29="NYJ",IMAGE("https://logos-world.net/wp-content/uploads/2020/07/New-York-Jets-Logo.png"),IF(G29="NE",IMAGE("https://purepng.com/public/uploads/large/new-england-patriots-logo-symbol-ucp.png"),IF(G29="BAL",IMAGE("https://1000logos.net/wp-content/uploads/2016/10/Baltimore-Ravens-Logo.png"),IF(G29="CLE",IMAGE("https://logos-world.net/wp-content/uploads/2020/05/Cleveland-Browns-Logo-2006-2014.png"),IF(G29="PIT",IMAGE("https://1000logos.net/wp-content/uploads/2017/06/Pittsburgh-Steelers-Logo.png"),IF(G29="CIN",IMAGE("https://logos-world.net/wp-content/uploads/2020/05/Cincinnati-Bengals-Logo.png"),IF(G29="HOU",IMAGE("https://cdn.wallpapersafari.com/15/25/Jnl2Yc.png"),IF(G29="JAX",IMAGE("https://1000logos.net/wp-content/uploads/2018/07/Jacksonville-Jaguars-Logo-1536x960.png"),IF(G29="IND",IMAGE("https://1000logos.net/wp-content/uploads/2016/12/Indianapolis-Colts-Logo-2048x1280.png"),IF(G29="TEN",IMAGE("https://img-s-msn-com.akamaized.net/tenant/amp/entityid/AA1YwbtK.img?w=720&h=720&m=6"),IF(G29="SF",IMAGE("https://logodownload.org/wp-content/uploads/2020/09/san-francisco-49ers-logo-2048x1220.png"),IF(G29="LAR",IMAGE("https://1000logos.net/wp-content/uploads/2018/07/Rams-Logo.png"),IF(G29="SEA",IMAGE("https://cdn.freebiesupply.com/images/large/2x/seattle-seahawks-logo-transparent.png"),IF(G29="AZ",IMAGE("https://logos-world.net/wp-content/uploads/2020/05/Arizona-Cardinals-Logo.png"),IF(G29="DAL",IMAGE("https://www.freepnglogos.com/uploads/dallas-cowboys-logo-22.png"),IF(G29="PHI",IMAGE("https://1000logos.net/wp-content/uploads/2017/05/Philadelphia-Eagles-Logo.png"),IF(G29="NYG",IMAGE("https://logosmarcas.net/wp-content/uploads/2020/07/New-York-Giants-Logo.png"),IF(G29="WSH",IMAGE("https://logodownload.org/wp-content/uploads/2020/09/washington-commanders-logo.png"),IF(G29="DET",IMAGE("https://logos-world.net/wp-content/uploads/2020/05/Detroit-Lions-Logo-2017-Present.png"),IF(G29="GB",IMAGE("https://logodownload.org/wp-content/uploads/2020/07/green-bay-packers-logo-1.png"),IF(G29="MIN",IMAGE("https://1000logos.net/wp-content/uploads/2017/06/Minnesota-Vikings-Logo-1965.png"),IF(G29="CHI",IMAGE("https://logos-world.net/wp-content/uploads/2020/05/Chicago-Bears-logo.png"),IF(G29="TB",IMAGE("https://logodownload.org/wp-content/uploads/2020/09/tampa-bay-buccaneers-logo.png"),IF(G29="NO",IMAGE("https://1000logos.net/wp-content/uploads/2017/04/New-Orleans-Saints-Logo.png"),IF(G29="ATL",IMAGE("https://logodownload.org/wp-content/uploads/2020/07/atlanta-falcons-logo-0.png"),IF(G29="CAR",IMAGE("https://logos-download.com/wp-content/uploads/2018/02/Carolina_Panthers_logo_blue.png"),""))))))))))))))))))))))))))))))))
A30: 5 | B30: {=INDEX('Playoffs Calc'!T9,0)} -> BUF | C30: =IF(B30="KC",IMAGE("https://logodownload.org/wp-content/uploads/2020/09/kansas-city-chiefs-logo.png"),IF(B30="LV",IMAGE("https://logodownload.org/wp-content/uploads/2020/09/las-vegas-raiders-logo-1-564x599.png"),IF(B30="DEN",IMAGE("https://logodownload.org/wp-content/uploads/2020/07/denver-broncos-logo-0.png"),IF(B30="LAC",IMAGE("https://logosmarcas.net/wp-content/uploads/2020/07/Los-Angeles-Chargers-logo.png"),IF(B30="BUF",IMAGE("https://logos-download.com/wp-content/uploads/2018/03/Buffalo_Bills_logo_blue.png"),IF(B30="MIA",IMAGE("https://logos-world.net/wp-content/uploads/2020/05/Miami-Dolphins-Logo.png"),IF(B30="NYJ",IMAGE("https://logos-world.net/wp-content/uploads/2020/07/New-York-Jets-Logo.png"),IF(B30="NE",IMAGE("https://purepng.com/public/uploads/large/new-england-patriots-logo-symbol-ucp.png"),IF(B30="BAL",IMAGE("https://1000logos.net/wp-content/uploads/2016/10/Baltimore-Ravens-Logo.png"),IF(B30="CLE",IMAGE("https://logos-world.net/wp-content/uploads/2020/05/Cleveland-Browns-Logo-2006-2014.png"),IF(B30="PIT",IMAGE("https://1000logos.net/wp-content/uploads/2017/06/Pittsburgh-Steelers-Logo.png"),IF(B30="CIN",IMAGE("https://logos-world.net/wp-content/uploads/2020/05/Cincinnati-Bengals-Logo.png"),IF(B30="HOU",IMAGE("https://cdn.wallpapersafari.com/15/25/Jnl2Yc.png"),IF(B30="JAX",IMAGE("https://1000logos.net/wp-content/uploads/2018/07/Jacksonville-Jaguars-Logo-1536x960.png"),IF(B30="IND",IMAGE("https://1000logos.net/wp-content/uploads/2016/12/Indianapolis-Colts-Logo-2048x1280.png"),IF(B30="TEN",IMAGE("https://img-s-msn-com.akamaized.net/tenant/amp/entityid/AA1YwbtK.img?w=720&h=720&m=6"),IF(B30="SF",IMAGE("https://logodownload.org/wp-content/uploads/2020/09/san-francisco-49ers-logo-2048x1220.png"),IF(B30="LAR",IMAGE("https://1000logos.net/wp-content/uploads/2018/07/Rams-Logo.png"),IF(B30="SEA",IMAGE("https://cdn.freebiesupply.com/images/large/2x/seattle-seahawks-logo-transparent.png"),IF(B30="AZ",IMAGE("https://logos-world.net/wp-content/uploads/2020/05/Arizona-Cardinals-Logo.png"),IF(B30="DAL",IMAGE("https://www.freepnglogos.com/uploads/dallas-cowboys-logo-22.png"),IF(B30="PHI",IMAGE("https://1000logos.net/wp-content/uploads/2017/05/Philadelphia-Eagles-Logo.png"),IF(B30="NYG",IMAGE("https://logosmarcas.net/wp-content/uploads/2020/07/New-York-Giants-Logo.png"),IF(B30="WSH",IMAGE("https://logodownload.org/wp-content/uploads/2020/09/washington-commanders-logo.png"),IF(B30="DET",IMAGE("https://logos-world.net/wp-content/uploads/2020/05/Detroit-Lions-Logo-2017-Present.png"),IF(B30="GB",IMAGE("https://logodownload.org/wp-content/uploads/2020/07/green-bay-packers-logo-1.png"),IF(B30="MIN",IMAGE("https://1000logos.net/wp-content/uploads/2017/06/Minnesota-Vikings-Logo-1965.png"),IF(B30="CHI",IMAGE("https://logos-world.net/wp-content/uploads/2020/05/Chicago-Bears-logo.png"),IF(B30="TB",IMAGE("https://logodownload.org/wp-content/uploads/2020/09/tampa-bay-buccaneers-logo.png"),IF(B30="NO",IMAGE("https://1000logos.net/wp-content/uploads/2017/04/New-Orleans-Saints-Logo.png"),IF(B30="ATL",IMAGE("https://logodownload.org/wp-content/uploads/2020/07/atlanta-falcons-logo-0.png"),IF(B30="CAR",IMAGE("https://logos-download.com/wp-content/uploads/2018/02/Carolina_Panthers_logo_blue.png"),"")))))))))))))))))))))))))))))))) | F30: 5 | G30: {=INDEX('Playoffs Calc'!T22,0)} -> SEA | H30: =IF(G30="KC",IMAGE("https://logodownload.org/wp-content/uploads/2020/09/kansas-city-chiefs-logo.png"),IF(G30="LV",IMAGE("https://logodownload.org/wp-content/uploads/2020/09/las-vegas-raiders-logo-1-564x599.png"),IF(G30="DEN",IMAGE("https://logodownload.org/wp-content/uploads/2020/07/denver-broncos-logo-0.png"),IF(G30="LAC",IMAGE("https://logosmarcas.net/wp-content/uploads/2020/07/Los-Angeles-Chargers-logo.png"),IF(G30="BUF",IMAGE("https://logos-download.com/wp-content/uploads/2018/03/Buffalo_Bills_logo_blue.png"),IF(G30="MIA",IMAGE("https://logos-world.net/wp-content/uploads/2020/05/Miami-Dolphins-Logo.png"),IF(G30="NYJ",IMAGE("https://logos-world.net/wp-content/uploads/2020/07/New-York-Jets-Logo.png"),IF(G30="NE",IMAGE("https://purepng.com/public/uploads/large/new-england-patriots-logo-symbol-ucp.png"),IF(G30="BAL",IMAGE("https://1000logos.net/wp-content/uploads/2016/10/Baltimore-Ravens-Logo.png"),IF(G30="CLE",IMAGE("https://logos-world.net/wp-content/uploads/2020/05/Cleveland-Browns-Logo-2006-2014.png"),IF(G30="PIT",IMAGE("https://1000logos.net/wp-content/uploads/2017/06/Pittsburgh-Steelers-Logo.png"),IF(G30="CIN",IMAGE("https://logos-world.net/wp-content/uploads/2020/05/Cincinnati-Bengals-Logo.png"),IF(G30="HOU",IMAGE("https://cdn.wallpapersafari.com/15/25/Jnl2Yc.png"),IF(G30="JAX",IMAGE("https://1000logos.net/wp-content/uploads/2018/07/Jacksonville-Jaguars-Logo-1536x960.png"),IF(G30="IND",IMAGE("https://1000logos.net/wp-content/uploads/2016/12/Indianapolis-Colts-Logo-2048x1280.png"),IF(G30="TEN",IMAGE("https://img-s-msn-com.akamaized.net/tenant/amp/entityid/AA1YwbtK.img?w=720&h=720&m=6"),IF(G30="SF",IMAGE("https://logodownload.org/wp-content/uploads/2020/09/san-francisco-49ers-logo-2048x1220.png"),IF(G30="LAR",IMAGE("https://1000logos.net/wp-content/uploads/2018/07/Rams-Logo.png"),IF(G30="SEA",IMAGE("https://cdn.freebiesupply.com/images/large/2x/seattle-seahawks-logo-transparent.png"),IF(G30="AZ",IMAGE("https://logos-world.net/wp-content/uploads/2020/05/Arizona-Cardinals-Logo.png"),IF(G30="DAL",IMAGE("https://www.freepnglogos.com/uploads/dallas-cowboys-logo-22.png"),IF(G30="PHI",IMAGE("https://1000logos.net/wp-content/uploads/2017/05/Philadelphia-Eagles-Logo.png"),IF(G30="NYG",IMAGE("https://logosmarcas.net/wp-content/uploads/2020/07/New-York-Giants-Logo.png"),IF(G30="WSH",IMAGE("https://logodownload.org/wp-content/uploads/2020/09/washington-commanders-logo.png"),IF(G30="DET",IMAGE("https://logos-world.net/wp-content/uploads/2020/05/Detroit-Lions-Logo-2017-Present.png"),IF(G30="GB",IMAGE("https://logodownload.org/wp-content/uploads/2020/07/green-bay-packers-logo-1.png"),IF(G30="MIN",IMAGE("https://1000logos.net/wp-content/uploads/2017/06/Minnesota-Vikings-Logo-1965.png"),IF(G30="CHI",IMAGE("https://logos-world.net/wp-content/uploads/2020/05/Chicago-Bears-logo.png"),IF(G30="TB",IMAGE("https://logodownload.org/wp-content/uploads/2020/09/tampa-bay-buccaneers-logo.png"),IF(G30="NO",IMAGE("https://1000logos.net/wp-content/uploads/2017/04/New-Orleans-Saints-Logo.png"),IF(G30="ATL",IMAGE("https://logodownload.org/wp-content/uploads/2020/07/atlanta-falcons-logo-0.png"),IF(G30="CAR",IMAGE("https://logos-download.com/wp-content/uploads/2018/02/Carolina_Panthers_logo_blue.png"),""))))))))))))))))))))))))))))))))
A31: 6 | B31: {=INDEX('Playoffs Calc'!T10,0)} -> CIN | C31: =IF(B31="KC",IMAGE("https://logodownload.org/wp-content/uploads/2020/09/kansas-city-chiefs-logo.png"),IF(B31="LV",IMAGE("https://logodownload.org/wp-content/uploads/2020/09/las-vegas-raiders-logo-1-564x599.png"),IF(B31="DEN",IMAGE("https://logodownload.org/wp-content/uploads/2020/07/denver-broncos-logo-0.png"),IF(B31="LAC",IMAGE("https://logosmarcas.net/wp-content/uploads/2020/07/Los-Angeles-Chargers-logo.png"),IF(B31="BUF",IMAGE("https://logos-download.com/wp-content/uploads/2018/03/Buffalo_Bills_logo_blue.png"),IF(B31="MIA",IMAGE("https://logos-world.net/wp-content/uploads/2020/05/Miami-Dolphins-Logo.png"),IF(B31="NYJ",IMAGE("https://logos-world.net/wp-content/uploads/2020/07/New-York-Jets-Logo.png"),IF(B31="NE",IMAGE("https://purepng.com/public/uploads/large/new-england-patriots-logo-symbol-ucp.png"),IF(B31="BAL",IMAGE("https://1000logos.net/wp-content/uploads/2016/10/Baltimore-Ravens-Logo.png"),IF(B31="CLE",IMAGE("https://logos-world.net/wp-content/uploads/2020/05/Cleveland-Browns-Logo-2006-2014.png"),IF(B31="PIT",IMAGE("https://1000logos.net/wp-content/uploads/2017/06/Pittsburgh-Steelers-Logo.png"),IF(B31="CIN",IMAGE("https://logos-world.net/wp-content/uploads/2020/05/Cincinnati-Bengals-Logo.png"),IF(B31="HOU",IMAGE("https://cdn.wallpapersafari.com/15/25/Jnl2Yc.png"),IF(B31="JAX",IMAGE("https://1000logos.net/wp-content/uploads/2018/07/Jacksonville-Jaguars-Logo-1536x960.png"),IF(B31="IND",IMAGE("https://1000logos.net/wp-content/uploads/2016/12/Indianapolis-Colts-Logo-2048x1280.png"),IF(B31="TEN",IMAGE("https://img-s-msn-com.akamaized.net/tenant/amp/entityid/AA1YwbtK.img?w=720&h=720&m=6"),IF(B31="SF",IMAGE("https://logodownload.org/wp-content/uploads/2020/09/san-francisco-49ers-logo-2048x1220.png"),IF(B31="LAR",IMAGE("https://1000logos.net/wp-content/uploads/2018/07/Rams-Logo.png"),IF(B31="SEA",IMAGE("https://cdn.freebiesupply.com/images/large/2x/seattle-seahawks-logo-transparent.png"),IF(B31="AZ",IMAGE("https://logos-world.net/wp-content/uploads/2020/05/Arizona-Cardinals-Logo.png"),IF(B31="DAL",IMAGE("https://www.freepnglogos.com/uploads/dallas-cowboys-logo-22.png"),IF(B31="PHI",IMAGE("https://1000logos.net/wp-content/uploads/2017/05/Philadelphia-Eagles-Logo.png"),IF(B31="NYG",IMAGE("https://logosmarcas.net/wp-content/uploads/2020/07/New-York-Giants-Logo.png"),IF(B31="WSH",IMAGE("https://logodownload.org/wp-content/uploads/2020/09/washington-commanders-logo.png"),IF(B31="DET",IMAGE("https://logos-world.net/wp-content/uploads/2020/05/Detroit-Lions-Logo-2017-Present.png"),IF(B31="GB",IMAGE("https://logodownload.org/wp-content/uploads/2020/07/green-bay-packers-logo-1.png"),IF(B31="MIN",IMAGE("https://1000logos.net/wp-content/uploads/2017/06/Minnesota-Vikings-Logo-1965.png"),IF(B31="CHI",IMAGE("https://logos-world.net/wp-content/uploads/2020/05/Chicago-Bears-logo.png"),IF(B31="TB",IMAGE("https://logodownload.org/wp-content/uploads/2020/09/tampa-bay-buccaneers-logo.png"),IF(B31="NO",IMAGE("https://1000logos.net/wp-content/uploads/2017/04/New-Orleans-Saints-Logo.png"),IF(B31="ATL",IMAGE("https://logodownload.org/wp-content/uploads/2020/07/atlanta-falcons-logo-0.png"),IF(B31="CAR",IMAGE("https://logos-download.com/wp-content/uploads/2018/02/Carolina_Panthers_logo_blue.png"),"")))))))))))))))))))))))))))))))) | F31: 6 | G31: {=INDEX('Playoffs Calc'!T23,0)} -> DAL | H31: =IF(G31="KC",IMAGE("https://logodownload.org/wp-content/uploads/2020/09/kansas-city-chiefs-logo.png"),IF(G31="LV",IMAGE("https://logodownload.org/wp-content/uploads/2020/09/las-vegas-raiders-logo-1-564x599.png"),IF(G31="DEN",IMAGE("https://logodownload.org/wp-content/uploads/2020/07/denver-broncos-logo-0.png"),IF(G31="LAC",IMAGE("https://logosmarcas.net/wp-content/uploads/2020/07/Los-Angeles-Chargers-logo.png"),IF(G31="BUF",IMAGE("https://logos-download.com/wp-content/uploads/2018/03/Buffalo_Bills_logo_blue.png"),IF(G31="MIA",IMAGE("https://logos-world.net/wp-content/uploads/2020/05/Miami-Dolphins-Logo.png"),IF(G31="NYJ",IMAGE("https://logos-world.net/wp-content/uploads/2020/07/New-York-Jets-Logo.png"),IF(G31="NE",IMAGE("https://purepng.com/public/uploads/large/new-england-patriots-logo-symbol-ucp.png"),IF(G31="BAL",IMAGE("https://1000logos.net/wp-content/uploads/2016/10/Baltimore-Ravens-Logo.png"),IF(G31="CLE",IMAGE("https://logos-world.net/wp-content/uploads/2020/05/Cleveland-Browns-Logo-2006-2014.png"),IF(G31="PIT",IMAGE("https://1000logos.net/wp-content/uploads/2017/06/Pittsburgh-Steelers-Logo.png"),IF(G31="CIN",IMAGE("https://logos-world.net/wp-content/uploads/2020/05/Cincinnati-Bengals-Logo.png"),IF(G31="HOU",IMAGE("https://cdn.wallpapersafari.com/15/25/Jnl2Yc.png"),IF(G31="JAX",IMAGE("https://1000logos.net/wp-content/uploads/2018/07/Jacksonville-Jaguars-Logo-1536x960.png"),IF(G31="IND",IMAGE("https://1000logos.net/wp-content/uploads/2016/12/Indianapolis-Colts-Logo-2048x1280.png"),IF(G31="TEN",IMAGE("https://img-s-msn-com.akamaized.net/tenant/amp/entityid/AA1YwbtK.img?w=720&h=720&m=6"),IF(G31="SF",IMAGE("https://logodownload.org/wp-content/uploads/2020/09/san-francisco-49ers-logo-2048x1220.png"),IF(G31="LAR",IMAGE("https://1000logos.net/wp-content/uploads/2018/07/Rams-Logo.png"),IF(G31="SEA",IMAGE("https://cdn.freebiesupply.com/images/large/2x/seattle-seahawks-logo-transparent.png"),IF(G31="AZ",IMAGE("https://logos-world.net/wp-content/uploads/2020/05/Arizona-Cardinals-Logo.png"),IF(G31="DAL",IMAGE("https://www.freepnglogos.com/uploads/dallas-cowboys-logo-22.png"),IF(G31="PHI",IMAGE("https://1000logos.net/wp-content/uploads/2017/05/Philadelphia-Eagles-Logo.png"),IF(G31="NYG",IMAGE("https://logosmarcas.net/wp-content/uploads/2020/07/New-York-Giants-Logo.png"),IF(G31="WSH",IMAGE("https://logodownload.org/wp-content/uploads/2020/09/washington-commanders-logo.png"),IF(G31="DET",IMAGE("https://logos-world.net/wp-content/uploads/2020/05/Detroit-Lions-Logo-2017-Present.png"),IF(G31="GB",IMAGE("https://logodownload.org/wp-content/uploads/2020/07/green-bay-packers-logo-1.png"),IF(G31="MIN",IMAGE("https://1000logos.net/wp-content/uploads/2017/06/Minnesota-Vikings-Logo-1965.png"),IF(G31="CHI",IMAGE("https://logos-world.net/wp-content/uploads/2020/05/Chicago-Bears-logo.png"),IF(G31="TB",IMAGE("https://logodownload.org/wp-content/uploads/2020/09/tampa-bay-buccaneers-logo.png"),IF(G31="NO",IMAGE("https://1000logos.net/wp-content/uploads/2017/04/New-Orleans-Saints-Logo.png"),IF(G31="ATL",IMAGE("https://logodownload.org/wp-content/uploads/2020/07/atlanta-falcons-logo-0.png"),IF(G31="CAR",IMAGE("https://logos-download.com/wp-content/uploads/2018/02/Carolina_Panthers_logo_blue.png"),""))))))))))))))))))))))))))))))))
A32: 7 | B32: {=INDEX('Playoffs Calc'!T11,0)} -> KC | C32: =IF(B32="KC",IMAGE("https://logodownload.org/wp-content/uploads/2020/09/kansas-city-chiefs-logo.png"),IF(B32="LV",IMAGE("https://logodownload.org/wp-content/uploads/2020/09/las-vegas-raiders-logo-1-564x599.png"),IF(B32="DEN",IMAGE("https://logodownload.org/wp-content/uploads/2020/07/denver-broncos-logo-0.png"),IF(B32="LAC",IMAGE("https://logosmarcas.net/wp-content/uploads/2020/07/Los-Angeles-Chargers-logo.png"),IF(B32="BUF",IMAGE("https://logos-download.com/wp-content/uploads/2018/03/Buffalo_Bills_logo_blue.png"),IF(B32="MIA",IMAGE("https://logos-world.net/wp-content/uploads/2020/05/Miami-Dolphins-Logo.png"),IF(B32="NYJ",IMAGE("https://logos-world.net/wp-content/uploads/2020/07/New-York-Jets-Logo.png"),IF(B32="NE",IMAGE("https://purepng.com/public/uploads/large/new-england-patriots-logo-symbol-ucp.png"),IF(B32="BAL",IMAGE("https://1000logos.net/wp-content/uploads/2016/10/Baltimore-Ravens-Logo.png"),IF(B32="CLE",IMAGE("https://logos-world.net/wp-content/uploads/2020/05/Cleveland-Browns-Logo-2006-2014.png"),IF(B32="PIT",IMAGE("https://1000logos.net/wp-content/uploads/2017/06/Pittsburgh-Steelers-Logo.png"),IF(B32="CIN",IMAGE("https://logos-world.net/wp-content/uploads/2020/05/Cincinnati-Bengals-Logo.png"),IF(B32="HOU",IMAGE("https://cdn.wallpapersafari.com/15/25/Jnl2Yc.png"),IF(B32="JAX",IMAGE("https://1000logos.net/wp-content/uploads/2018/07/Jacksonville-Jaguars-Logo-1536x960.png"),IF(B32="IND",IMAGE("https://1000logos.net/wp-content/uploads/2016/12/Indianapolis-Colts-Logo-2048x1280.png"),IF(B32="TEN",IMAGE("https://img-s-msn-com.akamaized.net/tenant/amp/entityid/AA1YwbtK.img?w=720&h=720&m=6"),IF(B32="SF",IMAGE("https://logodownload.org/wp-content/uploads/2020/09/san-francisco-49ers-logo-2048x1220.png"),IF(B32="LAR",IMAGE("https://1000logos.net/wp-content/uploads/2018/07/Rams-Logo.png"),IF(B32="SEA",IMAGE("https://cdn.freebiesupply.com/images/large/2x/seattle-seahawks-logo-transparent.png"),IF(B32="AZ",IMAGE("https://logos-world.net/wp-content/uploads/2020/05/Arizona-Cardinals-Logo.png"),IF(B32="DAL",IMAGE("https://www.freepnglogos.com/uploads/dallas-cowboys-logo-22.png"),IF(B32="PHI",IMAGE("https://1000logos.net/wp-content/uploads/2017/05/Philadelphia-Eagles-Logo.png"),IF(B32="NYG",IMAGE("https://logosmarcas.net/wp-content/uploads/2020/07/New-York-Giants-Logo.png"),IF(B32="WSH",IMAGE("https://logodownload.org/wp-content/uploads/2020/09/washington-commanders-logo.png"),IF(B32="DET",IMAGE("https://logos-world.net/wp-content/uploads/2020/05/Detroit-Lions-Logo-2017-Present.png"),IF(B32="GB",IMAGE("https://logodownload.org/wp-content/uploads/2020/07/green-bay-packers-logo-1.png"),IF(B32="MIN",IMAGE("https://1000logos.net/wp-content/uploads/2017/06/Minnesota-Vikings-Logo-1965.png"),IF(B32="CHI",IMAGE("https://logos-world.net/wp-content/uploads/2020/05/Chicago-Bears-logo.png"),IF(B32="TB",IMAGE("https://logodownload.org/wp-content/uploads/2020/09/tampa-bay-buccaneers-logo.png"),IF(B32="NO",IMAGE("https://1000logos.net/wp-content/uploads/2017/04/New-Orleans-Saints-Logo.png"),IF(B32="ATL",IMAGE("https://logodownload.org/wp-content/uploads/2020/07/atlanta-falcons-logo-0.png"),IF(B32="CAR",IMAGE("https://logos-download.com/wp-content/uploads/2018/02/Carolina_Panthers_logo_blue.png"),"")))))))))))))))))))))))))))))))) | F32: 7 | G32: {=INDEX('Playoffs Calc'!T24,0)} -> CHI | H32: =IF(G32="KC",IMAGE("https://logodownload.org/wp-content/uploads/2020/09/kansas-city-chiefs-logo.png"),IF(G32="LV",IMAGE("https://logodownload.org/wp-content/uploads/2020/09/las-vegas-raiders-logo-1-564x599.png"),IF(G32="DEN",IMAGE("https://logodownload.org/wp-content/uploads/2020/07/denver-broncos-logo-0.png"),IF(G32="LAC",IMAGE("https://logosmarcas.net/wp-content/uploads/2020/07/Los-Angeles-Chargers-logo.png"),IF(G32="BUF",IMAGE("https://logos-download.com/wp-content/uploads/2018/03/Buffalo_Bills_logo_blue.png"),IF(G32="MIA",IMAGE("https://logos-world.net/wp-content/uploads/2020/05/Miami-Dolphins-Logo.png"),IF(G32="NYJ",IMAGE("https://logos-world.net/wp-content/uploads/2020/07/New-York-Jets-Logo.png"),IF(G32="NE",IMAGE("https://purepng.com/public/uploads/large/new-england-patriots-logo-symbol-ucp.png"),IF(G32="BAL",IMAGE("https://1000logos.net/wp-content/uploads/2016/10/Baltimore-Ravens-Logo.png"),IF(G32="CLE",IMAGE("https://logos-world.net/wp-content/uploads/2020/05/Cleveland-Browns-Logo-2006-2014.png"),IF(G32="PIT",IMAGE("https://1000logos.net/wp-content/uploads/2017/06/Pittsburgh-Steelers-Logo.png"),IF(G32="CIN",IMAGE("https://logos-world.net/wp-content/uploads/2020/05/Cincinnati-Bengals-Logo.png"),IF(G32="HOU",IMAGE("https://cdn.wallpapersafari.com/15/25/Jnl2Yc.png"),IF(G32="JAX",IMAGE("https://1000logos.net/wp-content/uploads/2018/07/Jacksonville-Jaguars-Logo-1536x960.png"),IF(G32="IND",IMAGE("https://1000logos.net/wp-content/uploads/2016/12/Indianapolis-Colts-Logo-2048x1280.png"),IF(G32="TEN",IMAGE("https://img-s-msn-com.akamaized.net/tenant/amp/entityid/AA1YwbtK.img?w=720&h=720&m=6"),IF(G32="SF",IMAGE("https://logodownload.org/wp-content/uploads/2020/09/san-francisco-49ers-logo-2048x1220.png"),IF(G32="LAR",IMAGE("https://1000logos.net/wp-content/uploads/2018/07/Rams-Logo.png"),IF(G32="SEA",IMAGE("https://cdn.freebiesupply.com/images/large/2x/seattle-seahawks-logo-transparent.png"),IF(G32="AZ",IMAGE("https://logos-world.net/wp-content/uploads/2020/05/Arizona-Cardinals-Logo.png"),IF(G32="DAL",IMAGE("https://www.freepnglogos.com/uploads/dallas-cowboys-logo-22.png"),IF(G32="PHI",IMAGE("https://1000logos.net/wp-content/uploads/2017/05/Philadelphia-Eagles-Logo.png"),IF(G32="NYG",IMAGE("https://logosmarcas.net/wp-content/uploads/2020/07/New-York-Giants-Logo.png"),IF(G32="WSH",IMAGE("https://logodownload.org/wp-content/uploads/2020/09/washington-commanders-logo.png"),IF(G32="DET",IMAGE("https://logos-world.net/wp-content/uploads/2020/05/Detroit-Lions-Logo-2017-Present.png"),IF(G32="GB",IMAGE("https://logodownload.org/wp-content/uploads/2020/07/green-bay-packers-logo-1.png"),IF(G32="MIN",IMAGE("https://1000logos.net/wp-content/uploads/2017/06/Minnesota-Vikings-Logo-1965.png"),IF(G32="CHI",IMAGE("https://logos-world.net/wp-content/uploads/2020/05/Chicago-Bears-logo.png"),IF(G32="TB",IMAGE("https://logodownload.org/wp-content/uploads/2020/09/tampa-bay-buccaneers-logo.png"),IF(G32="NO",IMAGE("https://1000logos.net/wp-content/uploads/2017/04/New-Orleans-Saints-Logo.png"),IF(G32="ATL",IMAGE("https://logodownload.org/wp-content/uploads/2020/07/atlanta-falcons-logo-0.png"),IF(G32="CAR",IMAGE("https://logos-download.com/wp-content/uploads/2018/02/Carolina_Panthers_logo_blue.png"),""))))))))))))))))))))))))))))))))

Sheet More Stats
B1: AFC West | C1: Wins | D1: Losses | E1: Win % | G1: Home | H1: Away | I1: Division | J1: Conference | L1: PF | M1: PA | N1: DIFF | O1: PPG | Q1: AFC West | R1: AFC East | S1: AFC North | T1: AFC South | U1: NFC West | V1: NFC East | W1: NFC North | X1: NFC South
A2: =IMAGE("https://logodownload.org/wp-content/uploads/2020/09/kansas-city-chiefs-logo.png") | B2: KC | C2: {=INDEX('Standings Counter'!B20,0)} -> 10 | D2: {=INDEX('Standings Counter'!C20,0)} -> 7 | E2: =IF(AND(C2=0,D2=0),0,DIVIDE(C2,ADD(C2,D2))) -> 0.58823529 | G2: =CONCATENATE('Home Counter'!B20," - ",'Home Counter'!C20) -> 6 - 2 | H2: =CONCATENATE('Away Counter'!B20," - ",'Away Counter'!C20) -> 4 - 5 | I2: {=INDEX(Standings!D2,0)} -> 3 - 3 | J2: =CONCATENATE('Conference Counter'!B20," - ",'Conference Counter'!C20) -> 7 - 5 | L2: {=INDEX('PFPA Counter'!B20,0)} -> 354 | M2: {=INDEX('PFPA Counter'!C20,0)} -> 339 | N2: =minus(L2,M2) -> 15 | O2: =IF(AND(C2=0,D2=0),0,DIVIDE(L2,SUM(C2,D2))) -> 20.823529 | Q2: =CONCATENATE('AFC West Counter'!B20," - ",'AFC West Counter'!C20) -> 3 - 3 | R2: =CONCATENATE('AFC East Counter'!B20," - ",'AFC East Counter'!C20) -> 3 - 1 | S2: =CONCATENATE('AFC North Counter'!B20," - ",'AFC North Counter'!C20) -> 1 - 0 | T2: =CONCATENATE('AFC South Counter'!B20," - ",'AFC South Counter'!C20) -> 0 - 1 | U2: =CONCATENATE('NFC West Counter'!B20," - ",'NFC West Counter'!C20) -> 2 - 2 | V2: =CONCATENATE('NFC East Counter'!B20," - ",'NFC East Counter'!C20) -> 0 - 0 | W2: =CONCATENATE('NFC North Counter'!B20," - ",'NFC North Counter'!C20) -> 0 - 0 | X2: =CONCATENATE('NFC South Counter'!B20," - ",'NFC South Counter'!C20) -> 1 - 0
A3: =IMAGE("https://logodownload.org/wp-content/uploads/2020/09/las-vegas-raiders-logo-1-564x599.png") | B3: LV | C3: {=INDEX('Standings Counter'!D20,0)} -> 7 | D3: {=INDEX('Standings Counter'!E20,0)} -> 10 | E3: =IF(AND(C3=0,D3=0),0,DIVIDE(C3,ADD(C3,D3))) -> 0.41176471 | G3: =CONCATENATE('Home Counter'!D20," - ",'Home Counter'!E20) -> 5 - 3 | H3: =CONCATENATE('Away Counter'!D20," - ",'Away Counter'!E20) -> 2 - 7 | I3: {=INDEX(Standings!D3,0)} -> 2 - 4 | J3: =CONCATENATE('Conference Counter'!D20," - ",'Conference Counter'!E20) -> 6 - 6 | L3: {=INDEX('PFPA Counter'!D20,0)} -> 360 | M3: {=INDEX('PFPA Counter'!E20,0)} -> 367 | N3: =MINUS(L3,M3) -> -7 | O3: =IF(AND(C3=0,D3=0),0,DIVIDE(L3,SUM(C3,D3))) -> 21.176471 | Q3: =CONCATENATE('AFC West Counter'!D20," - ",'AFC West Counter'!E20) -> 2 - 4 | R3: =CONCATENATE('AFC East Counter'!D20," - ",'AFC East Counter'!E20) -> 2 - 2 | S3: =CONCATENATE('AFC North Counter'!D20," - ",'AFC North Counter'!E20) -> 1 - 0 | T3: =CONCATENATE('AFC South Counter'!D20," - ",'AFC South Counter'!E20) -> 1 - 0 | U3: =CONCATENATE('NFC West Counter'!D20," - ",'NFC West Counter'!E20) -> 1 - 3 | V3: =CONCATENATE('NFC East Counter'!D20," - ",'NFC East Counter'!E20) -> 0 - 0 | W3: =CONCATENATE('NFC North Counter'!D20," - ",'NFC North Counter'!E20) -> 0 - 0 | X3: =CONCATENATE('NFC South Counter'!D20," - ",'NFC South Counter'!E20) -> 0 - 1
